Workbook

Sheet Cover
B1: Project Compass
B3: Capital One Financial Corporation (NYSE: COF) — Acquisition of Discover Financial Services (NYSE: DFS)
B5: M&A DEAL ANALYSIS — ACCRETION / DILUTION, SYNERGY, REGULATORY & CREDIT CONCENTRATION RISK ASSESSMENT
B7: Prepared for: | C7: Investment Committee — Illustrative Deal Team Case Study
B8: Prepared by: | C8: M&A / FIG Coverage — Corporate Development
B9: Date: | C9: September 2026 (analysis reflects deal history through close, May 2025)
B10: Status: | C10: Transaction CLOSED — May 18, 2025 (used here as a fully-modelled illustrative case study)
B12: TRANSACTION SNAPSHOT
B13: Announcement date | C13: February 19, 2024
B14: Closing date | C14: May 18, 2025 (~14-month regulatory review)
B15: Transaction value (announced) | C15: $35.3 billion, 100% stock-for-stock
B16: Exchange ratio | C16: 1.0192 COF shares per DFS share (fixed)
B17: Premium to DFS unaffected price | C17: 26.6% (see Key Assumptions tab)
B18: Pro forma ownership | C18: ~60% COF / ~40% DFS legacy shareholders
B19: Run-rate synergies (by 2027) | C19: ~$2.7bn pre-tax ($1.5bn cost + $1.2bn network)
B20: One-time integration costs (guided) | C20: ~$2.8bn pre-tax
B21: Adjusted (non-GAAP) EPS accretion | C21: Double-digit in 2026; >15% in 2027 (mgmt guidance)
B22: Pro forma CET1 ratio at close | C22: ~14.0%
B23: Financial advisors | C23: Centerview Partners (COF) / PJT Partners (DFS)
B24: Key regulators | C24: Federal Reserve, OCC, Delaware State Bank Commissioner, DOJ (antitrust review)
B26: WHAT THIS MODEL COVERS
B27: 1. Key Assumptions — deal terms, tax/discount rate, synergy phase-in, purchase accounting inputs
B28: 2. Sources & Uses — all-stock consideration structure and transaction cost memo
B29: 3. Standalone Financials — FY2023A actuals for COF and DFS (last full year pre-signing)
B30: 4. Synergy Build — cost & network/revenue synergy ramp, 2025E–2030E, net of integration costs
B31: 5. Accretion / Dilution — adjusted (non-GAAP) and GAAP pro forma EPS bridge, 2025E–2028E
B32: 6. Sensitivity Analysis — EPS accretion vs. premium paid and synergy realization
B33: 7. Capital Impact — pro forma CET1 ratio bridge
B34: 8. Regulatory & Credit Concentration Risk — scored risk register + concentration metrics
B35: 9. Precedent Transactions — large-bank M&A benchmarking context
B37: Note on methodology: this is an independently constructed, fully-formula-driven analyst model built to reflect the actual disclosed terms and outcomes of the Capital One / Discover transaction. Deal value, exchange ratio, premium, synergy guidance, integration cost guidance, the initial non-PCD CECL allowance build, and the pro forma CET1 outcome are drawn directly from company filings, press releases and earnings calls — see the source notes on each tab. Multi-year projections, growth rates applied to standalone earnings, and certain purchase-accounting line items such as intangible amortization phasing and the RWA add are illustrative analyst estimates calibrated to land on management's disclosed outcomes, and are clearly flagged as such. This is a training/analysis exercise, not investment advice, and should not be relied upon as Capital One or Discover's actual reported financial results.

Sheet Key Assumptions
B1: Key Assumptions
B3: Blue = hardcoded input (sourced) · Black = formula · Yellow = key output check
B5: 1. SHARE PRICE, EXCHANGE RATIO & PREMIUM
B6: Discover (DFS) unaffected share price (2/16/24 close) | C6: 110.49 | E6: Source: DEFM14A / joint proxy statement, Feb-2024 press release
B7: Capital One (COF) unaffected share price (2/16/24 close) | C7: 137.24 | E7: Source: NYSE closing price, 2/16/2024
B8: Fixed exchange ratio (COF shares per DFS share) | C8: 1.0192 | E8: Source: Agreement & Plan of Merger, dated 2/19/2024
B9: Implied offer price per DFS share | C9: =C7*C8 -> 139.87501
B10: Implied premium to DFS unaffected price | C10: =C9/C6-1 -> 0.26595174 | E10: Company-disclosed premium: 26.6% — model reconciles to disclosed figure
B12: 2. TRANSACTION STRUCTURE & PRO FORMA OWNERSHIP
B13: New COF shares issued to DFS holders (mm) | C13: 257 | E13: Source: DEFM14A (Dec-2024 record date basis)
B14: COF diluted weighted-avg shares outstanding, FY2023A (mm) | C14: 383.4 | E14: Source: COF FY2023 10-K / Q4'23 earnings release
B15: Pro forma diluted shares outstanding (mm) | C15: =C13+C14 -> 640.4
B16: COF legacy shareholders — pro forma ownership % | C16: =C14/C15 -> 0.59868832
B17: DFS legacy shareholders — pro forma ownership % | C17: =C13/C15 -> 0.40131168 | E17: Check: should reconcile to disclosed ~60% / ~40% split
B18: Illustrative signing-date equity consideration (257mm shares × unaffected COF price $137.24) | C18: =C13*C7 -> 35270.68 | E18: Model-derived check figure (257mm shares × unaffected price), not identical to the disclosed $35.3bn deal value below
B19: Disclosed transaction value, per Feb-2024 announcement ($mm) | C19: 35300 | E19: Source: Capital One / Discover joint press release, 2/19/2024. NOTE: actual fair-value purchase consideration at
B20: → see Section 7 below ("Actual Closing Outcome") for the real $51.8bn figure and why it differs | E20: closing (May-2025) was $51.8bn, materially higher, since COF's share price appreciated between announcement and
B21: 3. TAX & DISCOUNT RATE ASSUMPTIONS
B22: Marginal tax rate applied to synergies / one-time costs | C22: 0.24 | E22: Illustrative blended U.S. federal + state statutory rate
B23: Illustrative cost of equity / discount rate | C23: 0.11 | E23: Illustrative — used for NPV / value-creation commentary only
B24: Standalone organic net income (to common) growth rate — simplified analyst assumption | C24: 0.07 | E24: A simplified single-rate assumption, informed by the long-term growth rate used in the S-4 fairness-opinion
E25: projections (which varies by year/entity, e.g. DFS ~13% in 2025 before ~7% long-term) — not a literal reproduction.
B26: 4. SYNERGY ASSUMPTIONS ($mm, pre-tax, run-rate by year)
C27: 2025 | D27: 2026 | E27: 2027 | F27: 2028 | G27: 2029 | H27: 2030
B28: Total run-rate synergies, pre-tax ($mm) — disclosed schedule | C28: 900 | D28: 2000 | E28: 2700 | F28: 2900 | G28: 3000 | H28: 3200 | I28: Source: S-4 — synergies provided to COF board / Centerview
B29: 2027 target — cost / expense synergies ($mm) | C29: 1500 | E29: Source: company guidance — "$1.5bn expense synergies by 2027"
B30: 2027 target — network / revenue synergies ($mm) | C30: 1200 | E30: Source: company guidance — "$1.2bn network synergies by 2027" (routing volume to Discover Network)
B31: Check: 2027 cost + network synergies vs. disclosed $2.7bn total | C31: =C29+C30-E28 -> 0 | E31: Should equal ~0 (2027 total synergies less sum of components)
B33: Cost / expense synergies, pre-tax ($mm), by year | C33: =C28*$C$29/$E$28 -> 500 | D33: =D28*$C$29/$E$28 -> 1111.1111 | E33: =E28*$C$29/$E$28 -> 1500 | F33: =F28*$C$29/$E$28 -> 1611.1111 | G33: =G28*$C$29/$E$28 -> 1666.6667 | H33: =H28*$C$29/$E$28 -> 1777.7778
B34: Network / revenue synergies, pre-tax ($mm), by year | C34: =C28*$C$30/$E$28 -> 400 | D34: =D28*$C$30/$E$28 -> 888.88889 | E34: =E28*$C$30/$E$28 -> 1200 | F34: =F28*$C$30/$E$28 -> 1288.8889 | G34: =G28*$C$30/$E$28 -> 1333.3333 | H34: =H28*$C$30/$E$28 -> 1422.2222
B36: 5. INTEGRATION COSTS & PURCHASE ACCOUNTING ASSUMPTIONS
B37: One-time integration costs, total pre-tax ($mm) | C37: 2800 | E37: Source: company guidance at announcement (actual costs later guided to modestly exceed this)
B38: Phasing — % of total integration cost incurred in 2025 / 2026 / 2027 | C38: 0.5 | D38: 0.35 | E38: 0.15 | F38: Illustrative phasing — heaviest in year of close/first full year
B39: Integration costs, pre-tax ($mm), by year | C39: =$C$37*C38 -> 1400 | D39: =$C$37*D38 -> 980 | E39: =$C$37*E38 -> 420 | F39: 0 | G39: 0 | H39: 0
B41: Initial CECL allowance build, non-PCD loans, pre-tax, via provision expense ($mm) | C41: 8800 | E41: Source: COF Q2'25 earnings — actual reported day-1 allowance build on close
B42: Timing: recognized in year of close (2025 only, GAAP-only item)
B43: Incremental intangible amortization, pre-tax ($mm/yr, declining) | C43: 150 | D43: 140 | E43: 120 | F43: 100 | H43: Illustrative — core deposit / customer relationship intangibles from purchase accounting
B45: 6. CAPITAL / CET1 ASSUMPTIONS
B46: COF standalone risk-weighted assets, FY2023A ($mm, approx.) | C46: 370000 | E46: Illustrative estimate consistent with disclosed FY2023 CET1 ratio & capital base
B47: COF standalone CET1 ratio, FY2023A | C47: 0.129 | E47: Source: COF FY2023 10-K
...

Sheet Sources & Uses
B1: Sources & Uses of Funds
B3: 100% stock-for-stock consideration — no cash or new debt raised at the holding-company level
B5: SOURCES | E5: USES
B6: New Capital One common equity issued (illustrative signing-date value) | C6: ='Key Assumptions'!C18 -> 35270.68 | E6: Purchase of Discover Financial Services common equity (illustrative signing-date value) | F6: ='Key Assumptions'!C18 -> 35270.68
B7: Cash on hand used | C7: =0 -> 0 | E7: New debt raised | F7: =0 -> 0
B9: Total Sources | C9: =SUM(C6:C7) -> 35270.68 | E9: Total Uses | F9: =SUM(F6:F7) -> 35270.68
B10: Check: Sources = Uses | C10: =C9-F9 -> 0
B11: Note: the $35.27bn above is this model's illustrative 257mm-shares x unaffected-price check, used for signing-date modeling consistency — not identical to the $35.3bn announced value or the $51.8bn actual closing consideration (Key Assumptions, Section 7).
B12: MEMO ITEMS (funded from combined operating cash flow / excess capital — not part of stock consideration)
B13: Estimated one-time integration & restructuring costs (pre-tax, cumulative) | C13: ='Key Assumptions'!C37 -> 2800
B14: Estimated advisory, legal & other transaction fees | C14: 150 | E14: Illustrative estimate for a transaction of this size and complexity
B15: Goodwill & other intangibles created (non-cash, balance sheet only) | C15: ='Key Assumptions'!C52 -> 7400
B16: Initial non-PCD CECL allowance build (non-cash, day-1 provision-expense charge) | C16: ='Key Assumptions'!C41 -> 8800
B18: FINANCIAL ADVISORS & KEY DEAL PARTIES
B19: Acquirer | C19: Capital One Financial Corporation (NYSE: COF)
B20: Target | C20: Discover Financial Services (NYSE: DFS)
B21: Acquirer financial advisor | C21: Centerview Partners
B22: Acquirer legal counsel | C22: Wachtell, Lipton, Rosen & Katz
B23: Target financial advisor | C23: PJT Partners
B24: Target legal counsel | C24: Cleary Gottlieb Steen & Hamilton
B25: Structure | C25: Two-step reverse triangular merger via Vega Merger Sub, Inc., followed by bank-level merger of Discover Bank into CONA
B26: Source: Agreement & Plan of Merger and joint proxy statement/prospectus (Form S-4/DEFM14A), Feb 2024

Sheet Standalone Financials
B1: Standalone Financials — FY2023A (Last Full Year Pre-Signing)
B3: All figures as reported; both companies' fiscal years end December 31
C5: Capital One (COF) | D5: Discover (DFS) | E5: Combined
B6: Total net revenue ($mm) | C6: 36800 | D6: 15794 | E6: =C6+D6 -> 52594
B7: Net income, total ($mm) | C7: 4887 | D7: 2904 | E7: =C7+D7 -> 7791
B8: Less: preferred stock dividends ($mm) | C8: 305 | D8: 0 | E8: =C8+D8 -> 305
B9: Net income available to common ($mm) | C9: =C7-C8 -> 4582 | D9: =D7-D8 -> 2904 | E9: =C9+D9 -> 7486
B10: Diluted weighted-avg shares outstanding (mm) | C10: 383.4 | D10: 257.9 | E10: =C10+D10 -> 641.3
B11: Diluted EPS ($) | C11: =C9/C10 -> 11.950965 | D11: =D9/D10 -> 11.260178 | E11: =E9/E10 -> 11.673164
B12: Total assets, period-end ($bn) | C12: 478.5 | D12: 145.1 | E12: =C12+D12 -> 623.6
B13: Total deposits, period-end ($bn) | C13: 348.4 | D13: 99.1 | E13: =C13+D13 -> 447.5
B14: CET1 capital ratio | C14: 0.129 | D14: 0.146 | E14: n/a
B15: Tangible book value per share ($) | C15: 99.78 | D15: 50.88 | E15: n/a
B17: Sources: COF FY2023 Form 10-K & Q4'23 earnings release (SEC EDGAR); DFS Q4'23/FY2023 earnings release (SEC EDGAR, Businesswire 1/16/2024).
B18: DFS total assets & deposits are illustrative estimates consistent with FY2023 10-K scale; CET1 ratios per respective 10-Ks.
B20: STANDALONE (NO-DEAL) FORWARD PROJECTION — combined net income to common, organic growth basis
B22: Organic growth rate applied (from Key Assumptions) | C22: ='Key Assumptions'!C24 -> 0.07
C24: FY2023A | D24: 2024E | E24: 2025E | F24: 2026E | G24: 2027E | H24: 2028E
B25: COF standalone net income to common ($mm) | C25: =C9 -> 4582 | D25: =C25*(1+$C$22) -> 4902.74 | E25: =D25*(1+$C$22) -> 5245.9318 | F25: =E25*(1+$C$22) -> 5613.147 | G25: =F25*(1+$C$22) -> 6006.0673 | H25: =G25*(1+$C$22) -> 6426.492
B26: DFS standalone net income to common ($mm) | C26: =D9 -> 2904 | D26: =C26*(1+$C$22) -> 3107.28 | E26: =D26*(1+$C$22) -> 3324.7896 | F26: =E26*(1+$C$22) -> 3557.5249 | G26: =F26*(1+$C$22) -> 3806.5516 | H26: =G26*(1+$C$22) -> 4073.0102
B27: Combined standalone net income to common ($mm) | C27: =C25+C26 -> 7486 | D27: =D25+D26 -> 8010.02 | E27: =E25+E26 -> 8570.7214 | F27: =F25+F26 -> 9170.6719 | G27: =G25+G26 -> 9812.6189 | H27: =H25+H26 -> 10499.502

Sheet Synergy Build
B1: Synergy Build & Integration Cost Ramp
B3: $ in millions, pre-tax unless noted · sourced to company guidance in Key Assumptions
C5: 2025 | D5: 2026 | E5: 2027 | F5: 2028 | G5: 2029 | H5: 2030
B6: Cost / expense synergies, pre-tax ($mm) | C6: ='Key Assumptions'!C33 -> 500 | D6: ='Key Assumptions'!D33 -> 1111.1111 | E6: ='Key Assumptions'!E33 -> 1500 | F6: ='Key Assumptions'!F33 -> 1611.1111 | G6: ='Key Assumptions'!G33 -> 1666.6667 | H6: ='Key Assumptions'!H33 -> 1777.7778
B7: Network / revenue synergies, pre-tax ($mm) | C7: ='Key Assumptions'!C34 -> 400 | D7: ='Key Assumptions'!D34 -> 888.88889 | E7: ='Key Assumptions'!E34 -> 1200 | F7: ='Key Assumptions'!F34 -> 1288.8889 | G7: ='Key Assumptions'!G34 -> 1333.3333 | H7: ='Key Assumptions'!H34 -> 1422.2222
B8: Total run-rate synergies, pre-tax ($mm) | C8: =C6+C7 -> 900 | D8: =D6+D7 -> 2000 | E8: =E6+E7 -> 2700 | F8: =F6+F7 -> 2900 | G8: =G6+G7 -> 3000 | H8: =H6+H7 -> 3200
B9: % of 2027 run-rate target achieved | C9: =C8/$E$8 -> 0.33333333 | D9: =D8/$E$8 -> 0.74074074 | E9: =E8/$E$8 -> 1 | F9: =F8/$E$8 -> 1.0740741 | G9: =G8/$E$8 -> 1.1111111 | H9: =H8/$E$8 -> 1.1851852
B11: Less: cash tax on synergies | C11: =-C8*'Key Assumptions'!$C$22 -> -216 | D11: =-D8*'Key Assumptions'!$C$22 -> -480 | E11: =-E8*'Key Assumptions'!$C$22 -> -648 | F11: =-F8*'Key Assumptions'!$C$22 -> -696 | G11: =-G8*'Key Assumptions'!$C$22 -> -720 | H11: =-H8*'Key Assumptions'!$C$22 -> -768
B12: After-tax synergies ($mm) | C12: =C8+C11 -> 684 | D12: =D8+D11 -> 1520 | E12: =E8+E11 -> 2052 | F12: =F8+F11 -> 2204 | G12: =G8+G11 -> 2280 | H12: =H8+H11 -> 2432
B14: ONE-TIME INTEGRATION COSTS
B15: Integration & restructuring costs, pre-tax ($mm) | C15: ='Key Assumptions'!C39 -> 1400 | D15: ='Key Assumptions'!D39 -> 980 | E15: ='Key Assumptions'!E39 -> 420 | F15: ='Key Assumptions'!F39 -> 0 | G15: ='Key Assumptions'!G39 -> 0 | H15: ='Key Assumptions'!H39 -> 0
B16: Tax benefit on integration costs | C16: =C15*'Key Assumptions'!$C$22 -> 336 | D16: =D15*'Key Assumptions'!$C$22 -> 235.2 | E16: =E15*'Key Assumptions'!$C$22 -> 100.8 | F16: =F15*'Key Assumptions'!$C$22 -> 0 | G16: =G15*'Key Assumptions'!$C$22 -> 0 | H16: =H15*'Key Assumptions'!$C$22 -> 0
B17: After-tax integration costs ($mm) | C17: =C15-C16 -> 1064 | D17: =D15-D16 -> 744.8 | E17: =E15-E16 -> 319.2 | F17: =F15-F16 -> 0 | G17: =G15-G16 -> 0 | H17: =H15-H16 -> 0
B19: Net synergy benefit after-tax, net of integration costs ($mm) | C19: =C12-C17 -> -380 | D19: =D12-D17 -> 775.2 | E19: =E12-E17 -> 1732.8 | F19: =F12-F17 -> 2204 | G19: =G12-G17 -> 2280 | H19: =H12-H17 -> 2432
B22: Synergy schedule sourced to S-4 fairness-opinion projections; cost/network split per company deal announcement (2/19/2024).
B23: Integration cost total per company guidance at announcement; actual costs were later guided to modestly exceed the original $2.8bn estimate.

Sheet Accretion-Dilution
B1: Pro Forma Accretion / (Dilution) Analysis
B3: Adjusted (non-GAAP) and GAAP EPS bridge, 2025E–2028E · $ in millions except per-share data
C5: 2025E | D5: 2026E | E5: 2027E | F5: 2028E
B6: A. STANDALONE (NO-DEAL) REFERENCE CASE
B7: COF standalone net income to common ($mm) | C7: ='Standalone Financials'!E25 -> 5245.9318 | D7: ='Standalone Financials'!F25 -> 5613.147 | E7: ='Standalone Financials'!G25 -> 6006.0673 | F7: ='Standalone Financials'!H25 -> 6426.492
B8: COF standalone diluted shares outstanding (mm) | C8: ='Key Assumptions'!$C$14 -> 383.4 | D8: ='Key Assumptions'!$C$14 -> 383.4 | E8: ='Key Assumptions'!$C$14 -> 383.4 | F8: ='Key Assumptions'!$C$14 -> 383.4
B9: COF standalone EPS ($) — the accretion/dilution benchmark | C9: =C7/C8 -> 13.68266 | D9: =D7/D8 -> 14.640446 | E9: =E7/E8 -> 15.665277 | F9: =F7/F8 -> 16.761847
B11: B. PRO FORMA COMBINED — ADJUSTED (NON-GAAP) BASIS
B12: Combined standalone net income to common ($mm) | C12: ='Standalone Financials'!E27 -> 8570.7214 | D12: ='Standalone Financials'!F27 -> 9170.6719 | E12: ='Standalone Financials'!G27 -> 9812.6189 | F12: ='Standalone Financials'!H27 -> 10499.502
B13: Plus: after-tax run-rate synergies ($mm) | C13: ='Synergy Build'!C12 -> 684 | D13: ='Synergy Build'!D12 -> 1520 | E13: ='Synergy Build'!E12 -> 2052 | F13: ='Synergy Build'!F12 -> 2204
B14: Adjusted pro forma net income to common ($mm) | C14: =C12+C13 -> 9254.7214 | D14: =D12+D13 -> 10690.672 | E14: =E12+E13 -> 11864.619 | F14: =F12+F13 -> 12703.502
B15: Pro forma diluted shares outstanding (mm) | C15: ='Key Assumptions'!$C$15 -> 640.4 | D15: ='Key Assumptions'!$C$15 -> 640.4 | E15: ='Key Assumptions'!$C$15 -> 640.4 | F15: ='Key Assumptions'!$C$15 -> 640.4
B16: Adjusted pro forma EPS ($) | C16: =C14/C15 -> 14.45147 | D16: =D14/D15 -> 16.693741 | E16: =E14/E15 -> 18.526888 | F16: =F14/F15 -> 19.836824
B17: Adjusted EPS accretion / (dilution) vs. COF standalone | C17: =C16/C9-1 -> 0.056188646 | D17: =D16/D9-1 -> 0.14024813 | E17: =E16/E9-1 -> 0.18267219 | F17: =F16/F9-1 -> 0.183451
B19: C. PRO FORMA COMBINED — GAAP REPORTED BASIS
B20: Adjusted pro forma net income to common ($mm) | C20: =C14 -> 9254.7214 | D20: =D14 -> 10690.672 | E20: =E14 -> 11864.619 | F20: =F14 -> 12703.502
B21: Less: after-tax one-time integration costs ($mm) | C21: =-'Synergy Build'!C17 -> -1064 | D21: =-'Synergy Build'!D17 -> -744.8 | E21: =-'Synergy Build'!E17 -> -319.2 | F21: =-'Synergy Build'!F17 -> 0
B22: Less: after-tax incremental intangible amortization ($mm) | C22: =-'Key Assumptions'!C43*(1-'Key Assumptions'!$C$22) -> -114 | D22: =-'Key Assumptions'!D43*(1-'Key Assumptions'!$C$22) -> -106.4 | E22: =-'Key Assumptions'!E43*(1-'Key Assumptions'!$C$22) -> -91.2 | F22: =-'Key Assumptions'!F43*(1-'Key Assumptions'!$C$22) -> -76
B23: Less: initial non-PCD CECL allowance build, after-tax ($mm, 2025 only) | C23: =-'Key Assumptions'!$C$41*(1-'Key Assumptions'!$C$22) -> -6688 | D23: 0 | E23: 0 | F23: 0
B24: GAAP pro forma net income to common ($mm) | C24: =SUM(C20:C23) -> 1388.7214 | D24: =SUM(D20:D23) -> 9839.4719 | E24: =SUM(E20:E23) -> 11454.219 | F24: =SUM(F20:F23) -> 12627.502
B25: GAAP pro forma EPS ($) | C25: =C24/C15 -> 2.1685219 | D25: =D24/D15 -> 15.364572 | E25: =E24/E15 -> 17.886038 | F25: =F24/F15 -> 19.718148
B26: GAAP EPS accretion / (dilution) vs. COF standalone | C26: =C25/C9-1 -> -0.84151314 | D26: =D25/D9-1 -> 0.049460645 | E26: =E25/E9-1 -> 0.14176327 | F26: =F25/F9-1 -> 0.17637088
B28: D. RETURN METRICS
B29: ROIC vs. $35.3bn announced deal value (illustrative analyst calc) | C29: =C14/'Key Assumptions'!$C$19 -> 0.26217341 | D29: =D14/'Key Assumptions'!$C$19 -> 0.3028519 | E29: =E14/'Key Assumptions'!$C$19 -> 0.33610819 | F29: =F14/'Key Assumptions'!$C$19 -> 0.35987259
B30: ROIC vs. $51.8bn actual closing purchase consideration (illustrative analyst calc) | C30: =C14/'Key Assumptions'!$C$66 -> 0.17868672 | D30: =D14/'Key Assumptions'!$C$66 -> 0.20641152 | E30: =E14/'Key Assumptions'!$C$66 -> 0.22907765 | F30: =F14/'Key Assumptions'!$C$66 -> 0.2452745
B31: ROIC above = adjusted pro forma NI (to common) / consideration — a simplified analyst proxy, NOT necessarily the
B32: same methodology company management uses for its own '16% ROIC and >20% IRR by 2027' guidance; the two ROIC figures
B33: above illustrate how much that ratio moves once actual ($51.8bn), rather than announced ($35.3bn), consideration is used.
B35: Note: management's own guidance is >15% accretion to adjusted non-GAAP EPS in 2027 and double-digit accretion in 2026,
B36: with GAAP results roughly breakeven in 2027 as remaining synergies phase in. This model's outputs are directionally consistent
B37: with (though not identical to) disclosed guidance, given simplified organic-growth and purchase-accounting assumptions above.
B38: Model convention: all figures on this tab are a SIGNING-DATE (Feb-2024) estimate using FY2023A actuals + illustrative
B39: growth/synergy assumptions — see 'Key Assumptions' tab, Section 7, for actual post-closing reported results for comparison.

Sheet Sensitivity
B1: Sensitivity Analysis — 2027E Adjusted EPS Accretion
B3: Fully formula-driven — recomputes exchange ratio, shares issued and synergy realization for each scenario
B5: REFERENCE / DRIVER CELLS
B6: DFS unaffected share price ($) | C6: ='Key Assumptions'!$C$6 -> 110.49
B7: COF unaffected share price ($) | C7: ='Key Assumptions'!$C$7 -> 137.24
B8: Reference DFS share count basis (mm) [= base new shares / base exchange ratio] | C8: ='Key Assumptions'!$C$13/'Key Assumptions'!$C$8 -> 252.15856
B9: COF pre-deal diluted shares (mm) | C9: ='Key Assumptions'!$C$14 -> 383.4
B10: 2027E combined standalone NI to common ($mm) — held constant across scenarios | C10: ='Standalone Financials'!G27 -> 9812.6189
B11: 2027E COF standalone EPS ($) — benchmark, held constant | C11: ='Accretion-Dilution'!E9 -> 15.665277
B12: 2027E base after-tax run-rate synergies ($mm) — scaled by realization % | C12: ='Synergy Build'!E12 -> 2052
B14: GRID 1 — 2027E ADJUSTED EPS ACCRETION / (DILUTION) vs. COF STANDALONE
B15: Rows = synergy realization vs. plan · Columns = premium paid to DFS unaffected price
B17: Synergy realization \ Premium | C17: 0.15 | D17: 0.2 | E17: 0.266 | F17: 0.3 | G17: 0.35
B18: 0.5 | C18: =(($C$10+$C$12*0.5)/($C$9+($C$6*(1+0.15)/$C$7)*$C$8))/$C$11-1 -> 0.12162775 | D18: =(($C$10+$C$12*0.5)/($C$9+($C$6*(1+0.2)/$C$7)*$C$8))/$C$11-1 -> 0.10347011 | E18: =(($C$10+$C$12*0.5)/($C$9+($C$6*(1+0.266)/$C$7)*$C$8))/$C$11-1 -> 0.080383377 | F18: =(($C$10+$C$12*0.5)/($C$9+($C$6*(1+0.3)/$C$7)*$C$8))/$C$11-1 -> 0.068863203 | G18: =(($C$10+$C$12*0.5)/($C$9+($C$6*(1+0.35)/$C$7)*$C$8))/$C$11-1 -> 0.052361184
B19: 0.75 | C19: =(($C$10+$C$12*0.75)/($C$9+($C$6*(1+0.15)/$C$7)*$C$8))/$C$11-1 -> 0.17471524 | D19: =(($C$10+$C$12*0.75)/($C$9+($C$6*(1+0.2)/$C$7)*$C$8))/$C$11-1 -> 0.15569818 | E19: =(($C$10+$C$12*0.75)/($C$9+($C$6*(1+0.266)/$C$7)*$C$8))/$C$11-1 -> 0.13151874 | F19: =(($C$10+$C$12*0.75)/($C$9+($C$6*(1+0.3)/$C$7)*$C$8))/$C$11-1 -> 0.1194533 | G19: =(($C$10+$C$12*0.75)/($C$9+($C$6*(1+0.35)/$C$7)*$C$8))/$C$11-1 -> 0.10217023
B20: 1 | C20: =(($C$10+$C$12*1)/($C$9+($C$6*(1+0.15)/$C$7)*$C$8))/$C$11-1 -> 0.22780273 | D20: =(($C$10+$C$12*1)/($C$9+($C$6*(1+0.2)/$C$7)*$C$8))/$C$11-1 -> 0.20792626 | E20: =(($C$10+$C$12*1)/($C$9+($C$6*(1+0.266)/$C$7)*$C$8))/$C$11-1 -> 0.1826541 | F20: =(($C$10+$C$12*1)/($C$9+($C$6*(1+0.3)/$C$7)*$C$8))/$C$11-1 -> 0.1700434 | G20: =(($C$10+$C$12*1)/($C$9+($C$6*(1+0.35)/$C$7)*$C$8))/$C$11-1 -> 0.15197928
B21: 1.1 | C21: =(($C$10+$C$12*1.1)/($C$9+($C$6*(1+0.15)/$C$7)*$C$8))/$C$11-1 -> 0.24903772 | D21: =(($C$10+$C$12*1.1)/($C$9+($C$6*(1+0.2)/$C$7)*$C$8))/$C$11-1 -> 0.22881748 | E21: =(($C$10+$C$12*1.1)/($C$9+($C$6*(1+0.266)/$C$7)*$C$8))/$C$11-1 -> 0.20310824 | F21: =(($C$10+$C$12*1.1)/($C$9+($C$6*(1+0.3)/$C$7)*$C$8))/$C$11-1 -> 0.19027944 | G21: =(($C$10+$C$12*1.1)/($C$9+($C$6*(1+0.35)/$C$7)*$C$8))/$C$11-1 -> 0.1719029
B22: 1.25 | C22: =(($C$10+$C$12*1.25)/($C$9+($C$6*(1+0.15)/$C$7)*$C$8))/$C$11-1 -> 0.28089021 | D22: =(($C$10+$C$12*1.25)/($C$9+($C$6*(1+0.2)/$C$7)*$C$8))/$C$11-1 -> 0.26015433 | E22: =(($C$10+$C$12*1.25)/($C$9+($C$6*(1+0.266)/$C$7)*$C$8))/$C$11-1 -> 0.23378945 | F22: =(($C$10+$C$12*1.25)/($C$9+($C$6*(1+0.3)/$C$7)*$C$8))/$C$11-1 -> 0.2206335 | G22: =(($C$10+$C$12*1.25)/($C$9+($C$6*(1+0.35)/$C$7)*$C$8))/$C$11-1 -> 0.20178833
B24: Highlighted cell = base case (100% synergy realization, 26.6% actual premium). Each cell independently recomputes
B25: the exchange ratio, new shares issued, pro forma share count and after-tax synergy dollars for that scenario.
B28: GRID 2 — 2027E GAAP EPS ACCRETION / (DILUTION), SYNERGY REALIZATION vs. INTEGRATION COST OVERRUN
B29: Rows = synergy realization vs. plan · Columns = total integration cost vs. $2.8bn guided
B31: 2027E GAAP pro forma NI build-up components ($mm)
B32: Adjusted PF NI at 100% synergies ($mm) | C32: ='Accretion-Dilution'!E14 -> 11864.619
B33: After-tax integration cost at 1.00x plan, negative ($mm) | C33: ='Accretion-Dilution'!E21 -> -319.2
B34: After-tax intangible amortization, fixed regardless of cost overrun, negative ($mm) | C34: ='Accretion-Dilution'!E22 -> -91.2
B35: Pro forma diluted shares (mm) | C35: ='Key Assumptions'!$C$15 -> 640.4
B37: Synergy realization \ Integration cost multiple | C37: 0.75 | D37: 1 | E37: 1.25 | F37: 1.5 | G37: 2
B38: 0.5 | C38: =((($C$32-'Accretion-Dilution'!$E$13*(1-0.5))+$C$34+$C$33*0.75)/$C$35)/$C$11-1 -> 0.047445502 | D38: =((($C$32-'Accretion-Dilution'!$E$13*(1-0.5))+$C$34+$C$33*1)/$C$35)/$C$11-1 -> 0.039490991 | E38: =((($C$32-'Accretion-Dilution'!$E$13*(1-0.5))+$C$34+$C$33*1.25)/$C$35)/$C$11-1 -> 0.03153648 | F38: =((($C$32-'Accretion-Dilution'!$E$13*(1-0.5))+$C$34+$C$33*1.5)/$C$35)/$C$11-1 -> 0.02358197 | G38: =((($C$32-'Accretion-Dilution'!$E$13*(1-0.5))+$C$34+$C$33*2)/$C$35)/$C$11-1 -> 0.0076729478
B39: 0.75 | C39: =((($C$32-'Accretion-Dilution'!$E$13*(1-0.75))+$C$34+$C$33*0.75)/$C$35)/$C$11-1 -> 0.098581644 | D39: =((($C$32-'Accretion-Dilution'!$E$13*(1-0.75))+$C$34+$C$33*1)/$C$35)/$C$11-1 -> 0.090627133 | E39: =((($C$32-'Accretion-Dilution'!$E$13*(1-0.75))+$C$34+$C$33*1.25)/$C$35)/$C$11-1 -> 0.082672622 | F39: =((($C$32-'Accretion-Dilution'!$E$13*(1-0.75))+$C$34+$C$33*1.5)/$C$35)/$C$11-1 -> 0.074718111 | G39: =((($C$32-'Accretion-Dilution'!$E$13*(1-0.75))+$C$34+$C$33*2)/$C$35)/$C$11-1 -> 0.058809089
B40: 1 | C40: =((($C$32-'Accretion-Dilution'!$E$13*(1-1))+$C$34+$C$33*0.75)/$C$35)/$C$11-1 -> 0.14971779 | D40: =((($C$32-'Accretion-Dilution'!$E$13*(1-1))+$C$34+$C$33*1)/$C$35)/$C$11-1 -> 0.14176327 | E40: =((($C$32-'Accretion-Dilution'!$E$13*(1-1))+$C$34+$C$33*1.25)/$C$35)/$C$11-1 -> 0.13380876 | F40: =((($C$32-'Accretion-Dilution'!$E$13*(1-1))+$C$34+$C$33*1.5)/$C$35)/$C$11-1 -> 0.12585425 | G40: =((($C$32-'Accretion-Dilution'!$E$13*(1-1))+$C$34+$C$33*2)/$C$35)/$C$11-1 -> 0.10994523
B41: 1.1 | C41: =((($C$32-'Accretion-Dilution'!$E$13*(1-1.1))+$C$34+$C$33*0.75)/$C$35)/$C$11-1 -> 0.17017224 | D41: =((($C$32-'Accretion-Dilution'!$E$13*(1-1.1))+$C$34+$C$33*1)/$C$35)/$C$11-1 -> 0.16221773 | E41: =((($C$32-'Accretion-Dilution'!$E$13*(1-1.1))+$C$34+$C$33*1.25)/$C$35)/$C$11-1 -> 0.15426322 | F41: =((($C$32-'Accretion-Dilution'!$E$13*(1-1.1))+$C$34+$C$33*1.5)/$C$35)/$C$11-1 -> 0.14630871 | G41: =((($C$32-'Accretion-Dilution'!$E$13*(1-1.1))+$C$34+$C$33*2)/$C$35)/$C$11-1 -> 0.13039969
B42: 1.25 | C42: =((($C$32-'Accretion-Dilution'!$E$13*(1-1.25))+$C$34+$C$33*0.75)/$C$35)/$C$11-1 -> 0.20085393 | D42: =((($C$32-'Accretion-Dilution'!$E$13*(1-1.25))+$C$34+$C$33*1)/$C$35)/$C$11-1 -> 0.19289942 | E42: =((($C$32-'Accretion-Dilution'!$E$13*(1-1.25))+$C$34+$C$33*1.25)/$C$35)/$C$11-1 -> 0.1849449 | F42: =((($C$32-'Accretion-Dilution'!$E$13*(1-1.25))+$C$34+$C$33*1.5)/$C$35)/$C$11-1 -> 0.17699039 | G42: =((($C$32-'Accretion-Dilution'!$E$13*(1-1.25))+$C$34+$C$33*2)/$C$35)/$C$11-1 -> 0.16108137
B44: Highlighted cell = base case (100% synergy realization, 1.00x guided integration cost — actual costs later guided to
B45: modestly exceed the original $2.8bn estimate, i.e. toward the 1.25x–1.50x columns).

Sheet Capital Impact
B1: Pro Forma Capital (CET1) Impact
B3: $ in millions unless noted · Part A is an ILLUSTRATIVE signing-date bridge; Part B is the ACTUAL reported outcome
B5: PART A — ILLUSTRATIVE SIGNING-DATE CET1 BRIDGE (analyst-constructed, calibrated to land near the disclosed ~14% outcome)
B6: COF standalone CET1 capital, FY2023A ($mm) | C6: ='Key Assumptions'!$C$48 -> 47730
B7: Plus: new common equity issued, at $35.3bn ANNOUNCED value (illustrative — see Part B for actual $51.8bn) | C7: ='Key Assumptions'!$C$19 -> 35300
B8: Less: goodwill & intangibles — ILLUSTRATIVE PLUG, not actual (see Part B for actual $13.78bn + $17.61bn) | C8: =-'Key Assumptions'!$C$52 -> -7400
B9: Less: initial non-PCD CECL allowance build, after-tax (provision-expense item) | C9: =-'Key Assumptions'!$C$41*(1-'Key Assumptions'!$C$22) -> -6688
B10: Less: after-tax transaction & integration costs incurred at/near close | C10: =-'Synergy Build'!C17 -> -1064
B11: Pro forma CET1 capital — illustrative bridge ($mm) | C11: =SUM(C6:C10) -> 67878
B13: COF standalone risk-weighted assets, FY2023A ($mm, illustrative estimate) | C13: ='Key Assumptions'!$C$46 -> 370000
B14: Plus: DFS acquired loan book — RWA added, illustrative estimate ($mm) | C14: ='Key Assumptions'!$C$49 -> 115000
B15: Pro forma risk-weighted assets — illustrative bridge ($mm) | C15: =SUM(C13:C14) -> 485000
B17: Pro forma CET1 ratio at close — MODEL (illustrative bridge) | C17: =C11/C15 -> 0.13995464
B18: Actual disclosed CET1 ratio, 6/30/2025 (quarter of close) — ACTUAL, for comparison | C18: ='Key Assumptions'!$C$78 -> 0.14
B19: Model vs. actual variance (pts) | C19: =C17-C18 -> -4.5360825e-05
B21: PART B — ACTUAL REPORTED OUTCOME (per COF Q2'25/Q3'25 10-Q — facts, not a model)
B22: Actual total purchase consideration at closing ($mm) | C22: ='Key Assumptions'!$C$66 -> 51793
B23: Actual goodwill recorded ($mm), after Q3'25 measurement-period adjustment | C23: 13778
B24: Actual identifiable intangible assets recorded ($mm), after Q3'25 measurement-period adjustment | C24: 17610
B25: Actual CET1 ratio, 12/31/2024 (pre-close) | C25: 0.135
B26: Actual CET1 ratio, 6/30/2025 (quarter of close) | C26: 0.14
B27: Actual change in CET1 ratio ($pts) | C27: =C26-C25 -> 0.005
B29: Note: the actual bridge involves substantially larger consideration, goodwill and intangibles than Part A's illustrative
B30: plug, because actual consideration reflects COF's May-2025 share price rather than the Feb-2024 announcement value, and yet
B31: the ACTUAL CET1 ratio still rose 0.5pt. We do not attempt to reconstruct the full actual RWA/capital-action bridge here
B32: (share buyback pauses, other capital actions, etc. are not fully disclosed at this level of granularity); Part B reports
B33: only the disclosed inputs and outputs, not an intermediate reconciliation.
B35: CONTEXT
B36: Both the illustrative Part A bridge and the actual Part B outcome point the same direction: the CET1 ratio improved,
B37: not worsened, through closing, despite a large one-time non-PCD CECL provision-expense charge and substantial goodwill
B38: and intangible-asset creation. This is a structural feature of an all-stock deal, since new common equity issuance is
B39: capital-supportive in a way that cash or debt financing would not have been, though the MAGNITUDE of Part A's
B40: illustrative bridge should not be read as a reconstruction of the actual purchase-accounting mechanics in Part B.
B41: This capital resilience is also relevant context for why regulators did not attach a materially larger capital-build
B42: condition to their approval, and for the timing of any post-2027 share buyback resumption.

Sheet Regulatory & Credit Risk
B1: Regulatory & Credit Concentration Risk Assessment
B3: Scored risk register (Likelihood x Impact, 1–5 scale) + credit concentration metrics
B5: RISK REGISTER
B6: Category | C6: Description | D6: Likelihood (1-5) | E6: Impact (1-5) | F6: Score | G6: Status / Actual Outcome | H6: Mitigant
B7: Antitrust / market concentration | C7: DOJ Antitrust Division review of combined share in U.S. general-purpose credit card issuance (~superprime/prime overlap) and payment network competition. | D7: 3 | E7: 4 | F7: =D7*E7 -> 12 | G7: RESOLVED — DOJ did not formally challenge the merger; consumer advocates (incl. Sen. Warren) urged a block but did not prevail. | H7: Discover and COF card portfolios are largely complementary by credit tier; Discover Network remains a distant #4 network, limiting horizontal network overlap concerns.
B8: Federal Reserve / OCC systemic & 'financial stability' review | C8: Bank holding company merger review under the Bank Merger Act / Bank Holding Company Act, including a public OCC hearing given deal size and consumer-lending concentration. | D8: 3 | E8: 5 | F8: =D8*E8 -> 15 | G8: RESOLVED — Fed and OCC granted conditional approval 4/18/2025 after ~14-month review (incl. 147-witness OCC public hearing). | H8: Combined entity's ~14% pro forma CET1 ratio and $265bn, 5-year community benefits plan directly addressed safety-and-soundness and community-impact concerns raised in the review.
B9: CRA / community reinvestment commitments | C9: Regulatory and public pressure to commit to community lending, investment and philanthropy as a condition of goodwill/approval. | D9: 4 | E9: 2 | F9: =D9*E9 -> 8 | G9: RESOLVED — $265bn, 5-year community benefits plan committed (July 2024). | H9: Plan pre-negotiated with community groups ahead of final approval to reduce approval friction; costs are modest relative to deal scale and phased over 5 years.
B10: Consumer protection / pre-existing litigation | C10: Shareholder and consumer class actions, incl. antitrust suit (paused pending court action) and a legacy COF savings-rate mis-selling matter. | D10: 3 | E10: 2 | F10: =D10*E10 -> 6 | G10: PARTIALLY RESOLVED — COF agreed to a $425mm settlement (360 Performance Savings rate claims) shortly before closing; antitrust class action remained pending/paused as of close. | H10: Settlement removed a key closing-conditions overhang; residual litigation risk is manageable relative to deal size and is a COF-legacy, not Discover-driven, exposure.
B11: Discover pre-existing regulatory/compliance issues | C11: Discover self-identified a card-tier misclassification issue (merchant interchange) and faced heightened compliance scrutiny and new CEO appointment (Dec-2023) ahead of the deal. | D11: 3 | E11: 3 | F11: =D11*E11 -> 9 | G11: MITIGATED AT DILIGENCE — priced into a 26.6% premium negotiated against this backdrop; COF's compliance/risk infrastructure is being extended to Discover post-close. | H11: COF's public commitment to integrate Discover into its compliance management program is an explicit closing condition and post-close workstream.
B12: Card / unsecured consumer credit concentration | C12: Pro forma combined credit card receivables materially exceed either standalone book (~$150bn COF domestic card + ~$102bn DFS card ≈ >$250bn), concentrating earnings in a single, cyclical asset class. | D12: 4 | E12: 4 | F12: =D12*E12 -> 16 | G12: ONGOING — inherent to the deal thesis; monitored via combined net charge-off and delinquency trends each quarter. | H12: Diversification benefit from DFS's direct-to-consumer deposit franchise and student-loan run-off book; combined scale supports through-the-cycle loss-absorption capacity.
B13: Subprime / near-prime borrower & macro sensitivity | C13: Both franchises skew toward revolving card balances sensitive to unemployment, wage growth and consumer-debt-service burden; NCOs at both companies rose sharply in 2023. | D13: 3 | E13: 4 | F13: =D13*E13 -> 12 | G13: ONGOING — sensitivity increases combined earnings volatility through a credit cycle; addressed via CECL reserving (incl. the $8.8bn day-1 build). | H13: The day-1 non-PCD CECL allowance build (recognized through provision expense; a separate PCD allowance is established via purchase accounting) materially front-loads reserve coverage on the acquired book, reducing forward loss-recognition volatility relative to an unreserved acquisition.
B14: Payment network execution / concentration risk | C14: Strategy depends on migrating COF debit and a portion of credit volume onto the smaller Discover Network (vs. Visa/Mastercard), which carries materially less merchant acceptance scale globally. | D14: 3 | E14: 3 | F14: =D14*E14 -> 9 | G14: ONGOING — network synergies ($1.2bn by 2027) are the single largest, most execution-dependent line of the synergy case. | H14: Phased volume migration (targeting ~$175bn of purchase volume onto Discover Network by 2027) rather than a one-time cutover; network already has broad U.S. acceptance.
B15: Integration & execution risk | C15: Large-scale technology, operations and cultural integration of two card-centric but organizationally distinct institutions. | D15: 3 | E15: 3 | F15: =D15*E15 -> 9 | G15: ONGOING — integration costs already guided to modestly exceed the original $2.8bn estimate. | H15: COF's public issuer/network experience (Capital One is itself a major issuer) and phased 2025-2027 cost-synergy ramp reduce (but do not eliminate) big-bang integration risk.
B16: Political / reputational risk | C16: Election-cycle scrutiny of large bank consolidation and consumer-lending concentration; vocal opposition from certain lawmakers and advocacy groups. | D16: 3 | E16: 2 | F16: =D16*E16 -> 6 | G16: RESOLVED AT APPROVAL — deal closed with full regulatory sign-off notwithstanding public opposition. | H16: Extensive, proactive community-benefits and compliance commitments reduced political leverage against approval.
B18: CREDIT CONCENTRATION — KEY METRICS
B19: COF domestic card receivables, FY2023A ($bn, approx.) | C19: ~$150bn | F19: Source: COF FY2023 10-K — card receivables exceeded $100bn during 2023 with continued growth
B20: DFS card receivables, FY2023A ($bn) | C20: ~$102bn (+13% YoY) | F20: Source: DFS FY2023 earnings release
B21: Pro forma combined card receivables ($bn, approx.) | C21: ~$250bn+ | F21: Illustrative sum — makes combined entity one of the largest U.S. card issuers by receivables
B22: DFS FY2023 provision for credit losses ($bn) | C22: $6.0bn (vs. $2.9bn net income) | F22: Source: DFS FY2023 results — provision more than doubled YoY
B23: COF FY2023 provision for credit losses ($bn) | C23: $10.4bn (+78% YoY) | F23: Source: COF FY2023 10-K/earnings release
B24: Combined day-1 CECL allowance build (non-PCD, pre-tax) | C24: $8.8bn | F24: Source: COF Q2'25 earnings — actual reported figure at close
B26: TAKEAWAY
B27: The Capital One/Discover combination is unusual among large-bank M&A in that it concentrates, rather than diversifies, credit risk, since both franchises are overwhelmingly unsecured consumer/card lenders. Regulators ultimately concluded this was manageable given (i) the deal's all-stock structure, which reduced the capital pressure a cash- or debt-funded deal would have created, (ii) an unusually large day-1 reserve build, and (iii) extensive community-benefit and compliance commitments, but the combined entity now carries meaningfully more single-asset-class (card) concentration risk than either standalone institution, which should be monitored closely through the credit cycle rather than treated as a one-time diligence item.

Sheet Precedent Transactions
B1: Precedent Transactions — Large U.S. Bank M&A Context
B3: Benchmarking premium, structure and synergy scale; figures per company filings/press releases
B5: Announced | C5: Acquirer | D5: Target | E5: Deal Value | F5: Structure | G5: Premium | H5: Cost Synergies | I5: Notes
B6: Feb-2024 | C6: Capital One | D6: Discover Financial Services | E6: $35.3bn | F6: 100% stock | G6: 26.6% | H6: $1.5bn (+$1.2bn network) | I6: Our subject transaction, the largest U.S. bank deal since the 2008 financial crisis; adds a proprietary payment network to an issuer for the first time since the Amex/Discover era.
B7: Feb-2019 | C7: BB&T | D7: SunTrust Banks (→ Truist) | E7: ~$66bn | F7: 100% stock (merger of equals) | G7: ~6.9% to SunTrust's undisturbed price | H7: $1.6bn pre-tax | I7: Largest bank M&A of the prior decade prior to COF/DFS; near-zero premium reflects true "merger of equals" structure and governance (co-CEO/board transition), unlike a control premium deal.
B8: Nov-2020 | C8: PNC Financial Services | D8: BBVA USA (BBVA's U.S. subsidiary) | E8: $11.6bn | F8: 100% cash | G8: N/A — acquisition of a subsidiary, no public minority shareholders | H8: ~$0.9bn guided | I8: Cash deal for a foreign parent's U.S. banking subsidiary; not a public-company premium transaction, included here as a scale/structure reference point only.
B9: Mar-2023 | C9: First Citizens BancShares | D9: Silicon Valley Bank (bridge bank, FDIC-assisted) | E9: ~$16.5bn discount to assets acquired | F9: FDIC-assisted purchase & assumption | G9: N/A — distressed/failed-bank acquisition, not a control premium | H9: N/A | I9: Not a premium M&A deal — included as a contrasting example of stressed-bank consolidation and to illustrate the very different regulatory pathway for a failed-bank vs. a negotiated control transaction.
B11: READ-ACROSS TO CAPITAL ONE / DISCOVER
B12: Premium (26.6%): materially above the near-zero premium in the BB&T/SunTrust "merger of equals," consistent with COF/DFS
B13: being a genuine control acquisition (COF ~60% pro forma ownership, COF board/management control) rather than an MOE, so a
B14: meaningfully higher premium is the expected, and disclosed, outcome of that structural difference, not an outlier.
B16: All-stock structure: shared by BB&T/SunTrust and COF/DFS, and is a key reason both deals avoided the capital drain a cash- or debt-funded deal would have created
B17: (see Capital Impact tab), a structural advantage over the cash-funded PNC/BBVA USA deal, which drew down acquirer capital.
B19: Regulatory duration: at ~14 months, the COF/DFS review was materially longer than a typical regional bank deal, reflecting
B20: its size, the payment-network dimension, and heightened scrutiny of large-bank consolidation in the current environment, and this is
B21: a risk factor worth flagging explicitly in any comparable future large-bank transaction timeline.
