Workbook

Sheet Cover
B2: KLARNA GROUP PLC (NYSE: KLAR)
B3: IPO Valuation & Pricing Analysis
B4: Integrated Three-Statement Model | DCF & Revenue-Multiple Valuation | Re-Rating Bridge ($46bn → $6.7bn → $15bn) | Credit-Loss & Profitability Stress Testing
B6: Prepared for: | C6: Illustrative Equity Research / IB Coverage Exercise
B7: Sector: | C7: Fintech / Buy-Now-Pay-Later / Digital Banking
B8: Ticker / Exchange: | C8: KLAR / NYSE
B9: IPO Date: | C9: September 10, 2025 (priced $40.00/sh, 9-Sep-25)
B10: Model Date / As-of: | C10: September 2, 2026 (post FY2025 & Q1 2026 actuals)
B11: Currency: | C11: USD, $ in millions unless noted (Klarna reports in USD from FY2024 onward; FY2021-22 SEK figures translated at disclosed/average FX)
B13: TABLE OF CONTENTS
B14: 1. | C14: Cover | D14: Deal summary, scope and key conclusions
B15: 2. | C15: Assumptions | D15: Historical data, operating drivers, WACC build, valuation-history inputs (all sourced)
B16: 3. | C16: Income Statement | D16: 3-statement model — FY2023A–FY2025A actuals + FY2026E–FY2030E projection
B17: 4. | C17: Balance Sheet | D17: Simplified lender balance sheet — loan book, funding, equity roll-forward
B18: 5. | C18: Cash Flow Statement | D18: Operating / investing / financing cash flow, linked to IS & BS
B19: 6. | C19: DCF Valuation | D19: Unlevered FCF, WACC, terminal value, implied equity value per share
B20: 7. | C20: Comps - Revenue Multiples | D20: EV/Revenue benchmarking vs. Affirm, PayPal, Block/Afterpay, Adyen
B21: 8. | C21: Re-Rating Bridge | D21: Decomposition of $46bn (2021) → $6.7bn (2022) → $15bn (2025 IPO)
B22: 9. | C22: Stress Testing | D22: Sensitivity grids: WACC/terminal growth; GMV growth/credit-loss rate
B23: 10. | C23: Scenario Summary | D23: Bear / Base / Bull profitability and credit scenarios
B24: 11. | C24: Football Field | D24: Valuation summary chart across all methodologies vs. actual IPO pricing
B26: KEY CONCLUSIONS (SUMMARY)
B27: • Klarna re-rated from a $45.6bn peak (Jun-2021 SoftBank round) to a $6.7bn trough (Jul-2022 down round, -85%) to a $15.1bn IPO price (Sep-2025) and a $19.65bn first-day close — a move driven far more by multiple compression/expansion (growth-at-all-costs → risk-off → disciplined profitable growth) than by revenue, which grew every year through the cycle.
B28: • This model builds an integrated 3-statement projection (FY2026E–FY2030E) off FY2025A actuals (Revenue $3.51bn, GMV $127.9bn, net loss attributable to shareholders $(294)mm, disclosed Adjusted Operating Profit $65mm), all reconciled to Klarna's actual filed 6-K financial statements (SEC EDGAR).
B29: • DCF (base case, ~10.95% WACC, 3.5% terminal growth → $9.1bn / $24.10 per share) sits BELOW the $15.1bn offer price — by design, this is flagged as an ILLUSTRATIVE cross-check rather than the primary valuation methodology, since ~83% of enterprise value comes from the Gordon Growth terminal value and a standard unlevered-FCF DCF is a simplification for a regulated, credit-exposed digital bank (see DCF tab methodology note). EV/Revenue comps (3.0x–5.5x FY2026E revenue) bracket the actual pricing far more comfortably; both are triangulated in the Football Field tab.
B30: • Stress testing flexes GMV growth, take rate, credit-loss rate (%GMV), WACC/terminal growth and a regulatory-capital-adequacy drag on loan growth to bound the valuation range and pressure-test the profitability inflection Klarna has reported since FY2024.
B32: COLOR CONVENTIONS
B33: Blue text | C33: Hardcoded input / assumption (sourced or user-editable)
B34: Black text | C34: Formula calculated within the same sheet
B35: Green text | C35: Formula linking to another sheet
B36: Yellow fill | C36: Key assumption or stress-test lever
B38: Sources: Klarna Group plc quarterly & annual earnings releases and press releases (2022–2026), Klarna Holding AB / Klarna Bank AB Annual Reports (2021–2023), Klarna F-1/IPO prospectus commentary, CNBC, Reuters, Bloomberg, Forbes, Morningstar, Axios, Sacra, Fox Business, Business of Apps, Simply Wall St, TechCrunch (Sep 2025–Feb 2026 reporting). Figures not individually disclosed by the Company (e.g., granular transaction-cost and opex splits, balance-sheet detail) are modeled estimates calibrated to reconcile to disclosed aggregates (Revenue, GMV, Adjusted Operating Profit, Net Income) and are flagged accordingly on each sheet. This is an independent, illustrative analysis; it is not investment advice and is not affiliated with Klarna Group plc.

Sheet Assumptions
A1: Assumptions & Operating Drivers
A2: All hardcoded inputs (blue) live on this tab and are referenced by every other sheet — change here to flow through the model.
A4: A. HISTORICAL FINANCIAL DATA — AS REPORTED BY KLARNA GROUP PLC
B5: ($ in millions, except take rate / loss rate) | C5: FY2021A | D5: FY2022A | E5: FY2023A | F5: FY2024A | G5: FY2025A
B6: Gross Merchandise Volume (GMV) | C6: 80300 | D6: 82837 | E6: 92465 | F6: 105015 | G6: 127900
B7: Total Revenue | C7: 1850 | D7: 1904 | E7: 2276 | F7: 2811 | G7: 3509
B8: Revenue growth, YoY | D8: =D7/C7-1 -> 0.029189189 | E8: =E7/D7-1 -> 0.19537815 | F8: =F7/E7-1 -> 0.23506151 | G8: =G7/F7-1 -> 0.24831021
B9: Take rate (Revenue / GMV) | C9: =C7/C6 -> 0.023038605 | D9: =D7/D6 -> 0.022984898 | E9: =E7/E6 -> 0.024614719 | F9: =F7/F6 -> 0.026767605 | G9: =G7/G6 -> 0.027435496
B10: Provision for credit losses | E10: 353 | F10: 495 | G10: 794
B11: Credit loss rate (% of GMV) | E11: =E10/E6 -> 0.0038176607 | F11: =F10/F6 -> 0.0047136123 | G11: =G10/G6 -> 0.006207975
B12: Adjusted operating profit / (loss) | C12: -520 | D12: -395 | E12: -49 | F12: 181 | G12: 65
B13: Net income / (loss) | C13: -830 | D13: -992 | E13: -244 | F13: 21 | G13: -294
B14: Active consumers (millions) | C14: 147 | E14: 93 | F14: 93 | G14: 118
A16: B. IPO & CAPITAL STRUCTURE INPUTS
B17: IPO price per share | C17: 40
B18: Day-1 closing price per share | C18: 45.82
B19: IPO implied equity value ($mm) | C19: 15100
B20: Implied equity value at Day-1 closing price ($mm) | C20: 19650
B21: Diluted shares outstanding at IPO (mm) | C21: 377.8
B22: Primary shares sold (mm) | C22: 5
B23: Secondary (selling shareholder) shares (mm) | C23: 29.3
B24: Gross IPO proceeds to Company ($mm) | C24: =C22*C17 -> 200
B25: Net debt at IPO (corporate, non-funding) ($mm) | C25: -1200
A27: C. PROJECTION DRIVERS — FY2026E–FY2030E (KEY ASSUMPTIONS = YELLOW)
C28: FY2026E | D28: FY2027E | E28: FY2028E | F28: FY2029E | G28: FY2030E
B29: GMV growth, YoY % | C29: 0.24 | D29: 0.2 | E29: 0.17 | F29: 0.14 | G29: 0.12
B30: Take rate (Revenue / GMV), % | C30: 0.0278 | D30: 0.0285 | E30: 0.0292 | F30: 0.0298 | G30: 0.0303
B31: Provision for credit losses (% of GMV) — STRESS LEVER | C31: 0.006 | D31: 0.0058 | E31: 0.0055 | F31: 0.0053 | G31: 0.005
B32: Processing & servicing costs (% of revenue) | C32: 0.2432 | D32: 0.2415 | E32: 0.2416 | F32: 0.2386 | G32: 0.2372
B33: Funding costs (% of revenue) | C33: 0.131 | D33: 0.13 | E33: 0.1301 | F33: 0.1285 | G33: 0.1277
B34: Technology & product development (% of revenue) | C34: 0.1002 | D34: 0.0961 | E34: 0.0919 | F34: 0.0905 | G34: 0.0891
B35: Sales & marketing (% of revenue) | C35: 0.1351 | D35: 0.1295 | E35: 0.1238 | F35: 0.122 | G35: 0.1201
B36: Customer service & operations (% of revenue) | C36: 0.0654 | D36: 0.0627 | E36: 0.0599 | F36: 0.059 | G36: 0.0581
B37: General & administrative (% of revenue) | C37: 0.0593 | D37: 0.0568 | E37: 0.0543 | F37: 0.0535 | G37: 0.0527
B38: D&A (% of revenue) | C38: 0.018 | D38: 0.017 | E38: 0.016 | F38: 0.015 | G38: 0.015
B39: Stock-based compensation (% of revenue) | C39: 0.045 | D39: 0.038 | E39: 0.032 | F39: 0.028 | G39: 0.025
B40: Restructuring & one-off items ($mm) | C40: 15 | D40: 10 | E40: 5 | F40: 0 | G40: 0
... B48: Target regulatory capital ratio (equity capital / net loans) — STRESS LEVER | C48: 0.02 | D48: 0.02 | E48: 0.025 | F48: 0.025 | G48: 0.03
A50: D. WACC BUILD & DCF ASSUMPTIONS
B51: Risk-free rate (10yr UST) | C51: 0.042
...

Sheet Income Statement
A1: Income Statement
A2: $ in millions except per-share and ratio data | FY2023A–FY2025A actual, FY2026E–FY2030E projected
B4: FY2023A | C4: FY2024A | D4: FY2025A | E4: FY2026E | F4: FY2027E | G4: FY2028E | H4: FY2029E | I4: FY2030E
A5: OPERATING VOLUME & TAKE RATE
A6: Gross Merchandise Volume (GMV) | B6: =Assumptions!E6 -> 92465 | C6: =Assumptions!F6 -> 105015 | D6: =Assumptions!G6 -> 127900 | E6: =D6*(1+Assumptions!C29) -> 158596 | F6: =E6*(1+Assumptions!D29) -> 190315.2 | G6: =F6*(1+Assumptions!E29) -> 222668.78 | H6: =G6*(1+Assumptions!F29) -> 253842.41 | I6: =H6*(1+Assumptions!G29) -> 284303.5
A7: GMV growth, YoY % | C7: =C6/B6-1 -> 0.13572703 | D7: =D6/C6-1 -> 0.21792125 | E7: =E6/D6-1 -> 0.24 | F7: =F6/E6-1 -> 0.2 | G7: =G6/F6-1 -> 0.17 | H7: =H6/G6-1 -> 0.14 | I7: =I6/H6-1 -> 0.12
A8: Take rate (Revenue / GMV) | B8: =Assumptions!E9 -> 0.024614719 | C8: =Assumptions!F9 -> 0.026767605 | D8: =Assumptions!G9 -> 0.027435496 | E8: =Assumptions!C30 -> 0.0278 | F8: =Assumptions!D30 -> 0.0285 | G8: =Assumptions!E30 -> 0.0292 | H8: =Assumptions!F30 -> 0.0298 | I8: =Assumptions!G30 -> 0.0303
A9: Total Revenue | B9: =B6*B8 -> 2276 | C9: =C6*C8 -> 2811 | D9: =D6*D8 -> 3509 | E9: =E6*E8 -> 4408.9688 | F9: =F6*F8 -> 5423.9832 | G9: =G6*G8 -> 6501.9285 | H9: =H6*H8 -> 7564.5039 | I9: =I6*I8 -> 8614.3962
A10: Revenue growth, YoY % | C10: =C9/B9-1 -> 0.23506151 | D10: =D9/C9-1 -> 0.24831021 | E10: =E9/D9-1 -> 0.25647444 | F10: =F9/E9-1 -> 0.23021583 | G10: =G9/F9-1 -> 0.19873684 | H10: =H9/G9-1 -> 0.16342466 | I10: =I9/H9-1 -> 0.13879195
A12: TRANSACTION COSTS (COST OF REVENUE)
A13: Credit loss rate (% of GMV) | B13: =Assumptions!E11 -> 0.0038176607 | C13: =Assumptions!F11 -> 0.0047136123 | D13: =Assumptions!G11 -> 0.006207975 | E13: =Assumptions!C31 -> 0.006 | F13: =Assumptions!D31 -> 0.0058 | G13: =Assumptions!E31 -> 0.0055 | H13: =Assumptions!F31 -> 0.0053 | I13: =Assumptions!G31 -> 0.005
A14: Provision for credit losses | B14: -353 | C14: -495 | D14: -794 | E14: =-E6*E13 -> -951.576 | F14: =-F6*F13 -> -1103.8282 | G14: =-G6*G13 -> -1224.6783 | H14: =-H6*H13 -> -1345.3648 | I14: =-I6*I13 -> -1421.5175
A15: Processing & servicing costs | B15: -541 | C15: -596 | D15: -809 | E15: =-E9*Assumptions!C32 -> -1072.2612 | F15: =-F9*Assumptions!D32 -> -1309.8919 | G15: =-G9*Assumptions!E32 -> -1570.8659 | H15: =-H9*Assumptions!F32 -> -1804.8906 | I15: =-I9*Assumptions!G32 -> -2043.3348
A16: Funding costs | B16: -297 | C16: -503 | D16: -667 | E16: =-E9*Assumptions!C33 -> -577.57491 | F16: =-F9*Assumptions!D33 -> -705.11782 | G16: =-G9*Assumptions!E33 -> -845.9009 | H16: =-H9*Assumptions!F33 -> -972.03876 | I16: =-I9*Assumptions!G33 -> -1100.0584
A17: Total transaction costs | B17: =SUM(B14:B16) -> -1191 | C17: =SUM(C14:C16) -> -1594 | D17: =SUM(D14:D16) -> -2270 | E17: =SUM(E14:E16) -> -2601.4121 | F17: =SUM(F14:F16) -> -3118.8379 | G17: =SUM(G14:G16) -> -3641.4451 | H17: =SUM(H14:H16) -> -4122.2942 | I17: =SUM(I14:I16) -> -4564.9107
A19: Transaction margin | B19: =B9+B17 -> 1085 | C19: =C9+C17 -> 1217 | D19: =D9+D17 -> 1239 | E19: =E9+E17 -> 1807.5567 | F19: =F9+F17 -> 2305.1453 | G19: =G9+G17 -> 2860.4834 | H19: =H9+H17 -> 3442.2097 | I19: =I9+I17 -> 4049.4855
A20: Transaction margin % | B20: =B19/B9 -> 0.47671353 | C20: =C19/C9 -> 0.43294201 | D20: =D19/D9 -> 0.35309205 | E20: =E19/E9 -> 0.40997266 | F20: =F19/F9 -> 0.42499123 | G20: =G19/G9 -> 0.43994384 | H20: =H19/H9 -> 0.45504765 | I20: =I19/I9 -> 0.4700835
A22: OPERATING EXPENSES
A23: Technology & product development | B23: -389 | C23: -444 | D23: -486 | E23: =-E9*Assumptions!C34 -> -441.77867 | F23: =-F9*Assumptions!D34 -> -521.24479 | G23: =-G9*Assumptions!E34 -> -597.52723 | H23: =-H9*Assumptions!F34 -> -684.58761 | I23: =-I9*Assumptions!G34 -> -767.5427
A24: Sales & marketing | B24: -381 | C24: -328 | D24: -414 | E24: =-E9*Assumptions!C35 -> -595.65168 | F24: =-F9*Assumptions!D35 -> -702.40582 | G24: =-G9*Assumptions!E35 -> -804.93875 | H24: =-H9*Assumptions!F35 -> -922.86948 | I24: =-I9*Assumptions!G35 -> -1034.589
A25: Customer service & operations | B25: -240 | C25: -203 | D25: -207 | E25: =-E9*Assumptions!C36 -> -288.34656 | F25: =-F9*Assumptions!D36 -> -340.08375 | G25: =-G9*Assumptions!E36 -> -389.46552 | H25: =-H9*Assumptions!F36 -> -446.30573 | I25: =-I9*Assumptions!G36 -> -500.49642
A26: General & administrative | B26: -270 | C26: -281 | D26: -306 | E26: =-E9*Assumptions!C37 -> -261.45185 | F26: =-F9*Assumptions!D37 -> -308.08225 | G26: =-G9*Assumptions!E37 -> -353.05472 | H26: =-H9*Assumptions!F37 -> -404.70096 | I26: =-I9*Assumptions!G37 -> -453.97868
A27: Total operating expenses | B27: =SUM(B23:B26) -> -1280 | C27: =SUM(C23:C26) -> -1256 | D27: =SUM(D23:D26) -> -1413 | E27: =SUM(E23:E26) -> -1587.2288 | F27: =SUM(F23:F26) -> -1871.8166 | G27: =SUM(G23:G26) -> -2144.9862 | H27: =SUM(H23:H26) -> -2458.4638 | I27: =SUM(I23:I26) -> -2756.6068
A29: Operating profit / (loss) before D&A | B29: =B19+B27 -> -195 | C29: =C19+C27 -> -39 | D29: =D19+D27 -> -174 | E29: =E19+E27 -> 220.32791 | F29: =F19+F27 -> 433.32868 | G29: =G19+G27 -> 715.49715 | H29: =H19+H27 -> 983.74597 | I29: =I19+I27 -> 1292.8787
A30: Margin % | B30: =B29/B9 -> -0.085676626 | C30: =C29/C9 -> -0.013874066 | D30: =D29/D9 -> -0.049586777 | E30: =E29/E9 -> 0.049972662 | F30: =F29/F9 -> 0.079891228 | G30: =G29/G9 -> 0.11004384 | H30: =H29/H9 -> 0.13004765 | I30: =I29/I9 -> 0.1500835
A32: Memo: Adjusted Operating Profit / (Loss), as reported (non-GAAP) | B32: -49 | C32: 181 | D32: 65
A34: BRIDGE TO NET INCOME (GAAP)
A35: Depreciation, amortization & impairments | B35: -128 | C35: -82 | D35: -55 | E35: =-E9*Assumptions!C38 -> -79.361438 | F35: =-F9*Assumptions!D38 -> -92.207714 | G35: =-G9*Assumptions!E38 -> -104.03086 | H35: =-H9*Assumptions!F38 -> -113.46756 | I35: =-I9*Assumptions!G38 -> -129.21594
A36: Operating profit / (loss) (GAAP) | B36: =B29+B35 -> -323 | C36: =C29+C35 -> -121 | D36: =D29+D35 -> -229 | E36: =E29+E35 -> 140.96647 | F36: =F29+F35 -> 341.12096 | G36: =G29+G35 -> 611.46629 | H36: =H29+H35 -> 870.27841 | I36: =I29+I35 -> 1163.6628
A38: Other income / (expense) | B38: 19 | C38: 154 | D38: -11 | E38: =Assumptions!C41 -> -20 | F38: =Assumptions!D41 -> 10 | G38: =Assumptions!E41 -> 40 | H38: =Assumptions!F41 -> 70 | I38: =Assumptions!G41 -> 100
A39: Pre-tax income / (loss) | B39: =B36+B38 -> -304 | C39: =C36+C38 -> 33 | D39: =D36+D38 -> -240 | E39: =E36+E38 -> 120.96647 | F39: =F36+F38 -> 351.12096 | G39: =G36+G38 -> 651.46629 | H39: =H36+H38 -> 940.27841 | I39: =I36+I38 -> 1263.6628
A40: Income tax (expense) / benefit | B40: 60 | C40: -12 | D40: -32 | E40: =-MAX(E39,0)*Assumptions!C42 -> -31.451282 | F40: =-MAX(F39,0)*Assumptions!D42 -> -91.291451 | G40: =-MAX(G39,0)*Assumptions!E42 -> -162.86657 | H40: =-MAX(H39,0)*Assumptions!F42 -> -235.0696 | I40: =-MAX(I39,0)*Assumptions!G42 -> -303.27906
A41: Net income / (loss), total | B41: =B39+B40 -> -244 | C41: =C39+C40 -> 21 | D41: =D39+D40 -> -272 | E41: =E39+E40 -> 89.515187 | F41: =F39+F40 -> 259.82951 | G41: =G39+G40 -> 488.59972 | H41: =H39+H40 -> 705.20881 | I41: =I39+I40 -> 960.3837
A42: Less: net income attributable to non-controlling interests | B42: -5 | C42: -18 | D42: -21 | E42: 0 | F42: 0 | G42: 0 | H42: 0 | I42: 0
A43: Net income / (loss) attributable to shareholders | B43: =B41+B42 -> -249 | C43: =C41+C42 -> 3 | D43: =D41+D42 -> -293 | E43: =E41+E42 -> 89.515187 | F43: =F41+F42 -> 259.82951 | G43: =G41+G42 -> 488.59972 | H43: =H41+H42 -> 705.20881 | I43: =I41+I42 -> 960.3837
A45: PER-SHARE DATA
A46: Diluted shares outstanding (mm) | D46: 372.2 | E46: =Assumptions!C45 -> 380 | F46: =Assumptions!D45 -> 383 | G46: =Assumptions!E45 -> 386 | H46: =Assumptions!F45 -> 389 | I46: =Assumptions!G45 -> 392
A47: Diluted EPS | D47: =D43/D46 -> -0.78721118 | E47: =E43/E46 -> 0.23556628 | F47: =F43/F46 -> 0.67840604 | G47: =G43/G46 -> 1.2658024 | H47: =H43/H46 -> 1.8128761 | I47: =I43/I46 -> 2.4499584
A49: FY2023A–FY2025A Provision for credit losses, Processing & servicing costs, Funding costs, Technology & product development, Sales & marketing, Customer service & operations, General & administrative, D&A, Other income/(expense) and tax are ALL exact figures from Klarna Group plc's filed 6-K “Consolidated Statements of Profit or Loss for the Years Ended December 31, 2025, 2024 and 2023” (SEC EDGAR, filed with FY2025 results, Feb-2026) — not model estimates. The “Adjusted Operating Profit” memo row is the Company's own separately-disclosed non-GAAP figure (see its comment for sourcing) and does not algebraically tie to the GAAP lines above because SBC is embedded within functional expense lines in the filed statement rather than broken out. FY2026E–FY2030E projected ratios are fully assumption-driven from the Assumptions tab, recalibrated for continuity off these exact FY2025A actuals, and can be flexed there (see Stress Testing tab for credit-loss and growth sensitivities).

Sheet Balance Sheet
A1: Balance Sheet
A2: $ in millions | Driver-based lender balance sheet (loans, deposits, funding, equity roll-forward) — FY2023A opening estimate, rolled forward through FY2030E, benchmarked against actual disclosed figures below
B4: FY2023A | C4: FY2024A | D4: FY2025A | E4: FY2026E | F4: FY2027E | G4: FY2028E | H4: FY2029E | I4: FY2030E
A5: ASSETS
A6: Net loans to consumers | B6: ='Income Statement'!B6*0.123 -> 11373.195 | C6: ='Income Statement'!C6*0.1206 -> 12664.809 | D6: ='Income Statement'!D6*0.118 -> 15092.2 | E6: ='Income Statement'!E6*Assumptions!C46 -> 18238.54 | F6: ='Income Statement'!F6*Assumptions!D46 -> 21505.618 | G6: ='Income Statement'!G6*Assumptions!E46 -> 24716.235 | H6: ='Income Statement'!H6*Assumptions!F46 -> 27668.823 | I6: ='Income Statement'!I6*Assumptions!G46 -> 30420.475
A7: Memo: Capital expenditure | B7: 52 | C7: 62 | D7: 74 | E7: ='Income Statement'!E9*Assumptions!C43 -> 88.179376 | F7: ='Income Statement'!F9*Assumptions!D43 -> 103.05568 | G7: ='Income Statement'!G9*Assumptions!E43 -> 117.03471 | H7: ='Income Statement'!H9*Assumptions!F43 -> 128.59657 | I7: ='Income Statement'!I9*Assumptions!G43 -> 137.83034
A8: Net PP&E & capitalized software | B8: 300 | C8: =B8+C7-ABS('Income Statement'!C35) -> 280 | D8: =C8+D7-ABS('Income Statement'!D35) -> 299 | E8: =D8+E7-ABS('Income Statement'!E35) -> 307.81794 | F8: =E8+F7-ABS('Income Statement'!F35) -> 318.6659 | G8: =F8+G7-ABS('Income Statement'!G35) -> 331.66976 | H8: =G8+H7-ABS('Income Statement'!H35) -> 346.79877 | I8: =H8+I7-ABS('Income Statement'!I35) -> 355.41316
A9: Other non-PPE assets | B9: 113 | C9: =0.05*'Income Statement'!C9 -> 140.55 | D9: =0.05*'Income Statement'!D9 -> 175.45 | E9: =0.05*'Income Statement'!E9 -> 220.44844 | F9: =0.05*'Income Statement'!F9 -> 271.19916 | G9: =0.05*'Income Statement'!G9 -> 325.09642 | H9: =0.05*'Income Statement'!H9 -> 378.2252 | I9: =0.05*'Income Statement'!I9 -> 430.71981
A10: Cash & cash equivalents | B10: 2000 | C10: ='Cash Flow Statement'!C27 -> 2243 | D10: ='Cash Flow Statement'!D27 -> 2371 | E10: ='Cash Flow Statement'!E27 -> 2650.1008 | F10: ='Cash Flow Statement'!F27 -> 3105.1938 | G10: ='Cash Flow Statement'!G27 -> 3788.8513 | H10: ='Cash Flow Statement'!H27 -> 4690.7372 | I10: ='Cash Flow Statement'!I27 -> 5857.8664
A11: Total assets | B11: =SUM(B6,B8,B9,B10) -> 13786.195 | C11: =SUM(C6,C8,C9,C10) -> 15328.359 | D11: =SUM(D6,D8,D9,D10) -> 17937.65 | E11: =SUM(E6,E8,E9,E10) -> 21416.907 | F11: =SUM(F6,F8,F9,F10) -> 25200.676 | G11: =SUM(G6,G8,G9,G10) -> 29161.853 | H11: =SUM(H6,H8,H9,H10) -> 33084.584 | I11: =SUM(I6,I8,I9,I10) -> 37064.474
A13: LIABILITIES
A14: Consumer deposits | B14: =B6*0.7 -> 7961.2365 | C14: =C6*0.75 -> 9498.6068 | D14: =D6*0.76 -> 11470.072 | E14: =E6*Assumptions!C47 -> 13131.749 | F14: =F6*Assumptions!D47 -> 15914.157 | G14: =G6*Assumptions!E47 -> 18784.339 | H14: =H6*Assumptions!F47 -> 21581.682 | I14: =I6*Assumptions!G47 -> 24336.38
A15: Other borrowings (warehouse facilities & ABS) | B15: =B6-B14 -> 3411.9585 | C15: =C6-C14 -> 3166.2022 | D15: =D6-D14 -> 3622.128 | E15: =E6-E14 -> 5106.7912 | F15: =F6-F14 -> 5591.4606 | G15: =G6-G14 -> 5931.8964 | H15: =H6-H14 -> 6087.1411 | I15: =I6-I14 -> 6084.095
A16: Other liabilities | B16: 113 | C16: =0.05*'Income Statement'!C9 -> 140.55 | D16: =0.05*'Income Statement'!D9 -> 175.45 | E16: =0.05*'Income Statement'!E9 -> 220.44844 | F16: =0.05*'Income Statement'!F9 -> 271.19916 | G16: =0.05*'Income Statement'!G9 -> 325.09642 | H16: =0.05*'Income Statement'!H9 -> 378.2252 | I16: =0.05*'Income Statement'!I9 -> 430.71981
A17: Total liabilities | B17: =SUM(B14:B16) -> 11486.195 | C17: =SUM(C14:C16) -> 12805.359 | D17: =SUM(D14:D16) -> 15267.65 | E17: =SUM(E14:E16) -> 18458.988 | F17: =SUM(F14:F16) -> 21776.817 | G17: =SUM(G14:G16) -> 25041.331 | H17: =SUM(H14:H16) -> 28047.048 | I17: =SUM(I14:I16) -> 30851.195
A19: EQUITY
A20: Common stock & additional paid-in capital | B20: 4300 | C20: =B20+'Cash Flow Statement'!C8 -> 4520 | D20: =C20+Assumptions!C24+'Cash Flow Statement'!D8 -> 4960 | E20: =D20+'Cash Flow Statement'!E8 -> 5158.4036 | F20: =E20+'Cash Flow Statement'!F8 -> 5364.515 | G20: =F20+'Cash Flow Statement'!G8 -> 5572.5767 | H20: =G20+'Cash Flow Statement'!H8 -> 5784.3828 | I20: =H20+'Cash Flow Statement'!I8 -> 5999.7427
A21: Retained earnings / (accumulated deficit) | B21: -2000 | C21: =B21+'Income Statement'!C43 -> -1997 | D21: =C21+'Income Statement'!D43 -> -2290 | E21: =D21+'Income Statement'!E43 -> -2200.4848 | F21: =E21+'Income Statement'!F43 -> -1940.6553 | G21: =F21+'Income Statement'!G43 -> -1452.0556 | H21: =G21+'Income Statement'!H43 -> -746.84677 | I21: =H21+'Income Statement'!I43 -> 213.53693
A22: Total equity | B22: =B20+B21 -> 2300 | C22: =C20+C21 -> 2523 | D22: =D20+D21 -> 2670 | E22: =E20+E21 -> 2957.9188 | F22: =F20+F21 -> 3423.8597 | G22: =G20+G21 -> 4120.5211 | H22: =H20+H21 -> 5037.536 | I22: =I20+I21 -> 6213.2796
A24: Total liabilities & equity | B24: =B17+B22 -> 13786.195 | C24: =C17+C22 -> 15328.359 | D24: =D17+D22 -> 17937.65 | E24: =E17+E22 -> 21416.907 | F24: =F17+F22 -> 25200.676 | G24: =G17+G22 -> 29161.853 | H24: =H17+H22 -> 33084.584 | I24: =I17+I22 -> 37064.474
A26: Balance check (Assets − Liab.&Equity) | B26: =B11-B24 -> 0 | C26: =C11-C24 -> 0 | D26: =D11-D24 -> 0 | E26: =E11-E24 -> 0 | F26: =F11-F24 -> 0 | G26: =G11-G24 -> 0 | H26: =H11-H24 -> 0 | I26: =I11-I24 -> 0
A28: MEMO: KEY BALANCE SHEET RATIOS
A29: Net loans / trailing GMV | B29: =B6/'Income Statement'!B6 -> 0.123 | C29: =C6/'Income Statement'!C6 -> 0.1206 | D29: =D6/'Income Statement'!D6 -> 0.118 | E29: =E6/'Income Statement'!E6 -> 0.115 | F29: =F6/'Income Statement'!F6 -> 0.113 | G29: =G6/'Income Statement'!G6 -> 0.111 | H29: =H6/'Income Statement'!H6 -> 0.109 | I29: =I6/'Income Statement'!I6 -> 0.107
A30: Consumer deposits / net loans | B30: =B14/B6 -> 0.7 | C30: =C14/C6 -> 0.75 | D30: =D14/D6 -> 0.76 | E30: =E14/E6 -> 0.72 | F30: =F14/F6 -> 0.74 | G30: =G14/G6 -> 0.76 | H30: =H14/H6 -> 0.78 | I30: =I14/I6 -> 0.8
A31: Total assets / total equity (leverage) | B31: =B11/B22 -> 5.9939978 | C31: =C11/C22 -> 6.0754495 | D31: =D11/D22 -> 6.718221 | E31: =E11/E22 -> 7.2405325 | F31: =F11/F22 -> 7.3603123 | G31: =G11/G22 -> 7.0772244 | H31: =H11/H22 -> 6.5676125 | I31: =I11/I22 -> 5.965364
A33: MEMO: CAPITAL ADEQUACY (ILLUSTRATIVE)
A34: Total equity ($mm) | B34: =B22 -> 2300 | C34: =C22 -> 2523 | D34: =D22 -> 2670 | E34: =E22 -> 2957.9188 | F34: =F22 -> 3423.8597 | G34: =G22 -> 4120.5211 | H34: =H22 -> 5037.536 | I34: =I22 -> 6213.2796
A35: Net loans to consumers ($mm) | B35: =B6 -> 11373.195 | C35: =C6 -> 12664.809 | D35: =D6 -> 15092.2 | E35: =E6 -> 18238.54 | F35: =F6 -> 21505.618 | G35: =G6 -> 24716.235 | H35: =H6 -> 27668.823 | I35: =I6 -> 30420.475
A36: Illustrative capital ratio (Total equity / Net loans) | B36: =B34/B35 -> 0.20222989 | C36: =C34/C35 -> 0.19921343 | D36: =D34/D35 -> 0.17691258 | E36: =E34/E35 -> 0.16217958 | F36: =F34/F35 -> 0.15920769 | G36: =G34/G35 -> 0.16671314 | H36: =H34/H35 -> 0.18206542 | I36: =I34/I35 -> 0.20424663
A37: Target regulatory capital ratio (Assumptions tab) | E37: =Assumptions!C48 -> 0.02 | F37: =Assumptions!D48 -> 0.02 | G37: =Assumptions!E48 -> 0.025 | H37: =Assumptions!F48 -> 0.025 | I37: =Assumptions!G48 -> 0.03
A38: Surplus / (shortfall) vs. target | E38: =E36-E37 -> 0.14217958 | F38: =F36-F37 -> 0.13920769 | G38: =G36-G37 -> 0.14171314 | H38: =H36-H37 -> 0.15706542 | I38: =I36-I37 -> 0.17424663
A40: Illustrative capital-adequacy check: Total equity here is the Company-wide consolidated equity base (NOT a formal CET1/RWA calculation under Basel III/CRR, which would require risk-weighting by product and jurisdiction), benchmarked against net loans as a simple leverage proxy for the regulated lending entity, Klarna Bank AB. This memo is a monitoring check, not a fully articulated capital-planning model, and the ratio below should NOT be read as, or compared directly to, Klarna's actual reported regulatory capital ratios. The DCF tab separately deducts an explicit regulatory-capital-drag charge from unlevered FCF as loans grow, reflecting that a portion of loan growth cannot be funded by deposits/debt alone — but the Balance Sheet's equity roll-forward (retained earnings + paid-in capital) is driven independently by GAAP net income and is not mechanically forced to track the target ratio. Flex the target ratio on the Assumptions tab to stress-test capital intensity.
A41: REFERENCE: ACTUAL DISCLOSED BALANCE SHEET DATA (JUNE 2025, PER SEC FILING) — NOT MODELED ABOVE
A42: Cash and cash equivalents | D42: 5504
A43: Consumer receivables, net | D43: 9950
A44: Consumer deposits | D44: 13970
A46: Modeled Net loans to consumers, FY2025A (for reference) | D46: =D6 -> 15092.2
A47: Modeled Consumer deposits, FY2025A (for reference) | D47: =D14 -> 11470.072
A48: This tab is deliberately NOT a replica of Klarna's actual statutory balance sheet (which, per the Company's SEC filings, is considerably more granular — separately staged receivables, allowance for credit losses, multiple funding facilities by type/tenor/jurisdiction, and a full regulatory capital/RWA build under Basel III/CRR). It is a driver-based proxy calibrated to move sensibly with GMV, revenue and net income for 3-statement linkage and DCF/capital-drag purposes, cross-checked here against real disclosed figures for transparency about the gap. The Cash Flow Statement, DCF and capital-adequacy outputs on this workbook should be read with that limitation in mind — for balance-sheet-level precision (e.g., actual receivables staging or funding-facility terms), refer to Klarna's SEC filings directly.
A49: FY2023A opening balances (Cash, PP&E, paid-in capital, accumulated deficit) are illustrative estimates calibrated to be broadly consistent with disclosed cumulative fundraising (~$3.7bn pre-IPO, per Sacra) and disclosed annual net losses (Assumptions tab). All FY2024A–FY2030E balances are formula-driven off the Income Statement and Assumptions tabs and roll forward consistently; the Balance check row should equal zero (or a de minimis rounding residual) by construction — see Cash Flow Statement tab for the linking mechanics.

Sheet Cash Flow Statement
A1: Cash Flow Statement
A2: $ in millions | Indirect method, fully linked to the Income Statement and Balance Sheet | FY2024A–FY2030E (FY2023A is the opening balance-sheet anchor)
B4: FY2023A | C4: FY2024A | D4: FY2025A | E4: FY2026E | F4: FY2027E | G4: FY2028E | H4: FY2029E | I4: FY2030E
A5: CASH FLOW FROM OPERATING ACTIVITIES
A6: Net income / (loss) | C6: ='Income Statement'!C43 -> 3 | D6: ='Income Statement'!D43 -> -293 | E6: ='Income Statement'!E43 -> 89.515187 | F6: ='Income Statement'!F43 -> 259.82951 | G6: ='Income Statement'!G43 -> 488.59972 | H6: ='Income Statement'!H43 -> 705.20881 | I6: ='Income Statement'!I43 -> 960.3837
A7: (+) Depreciation, amortization & impairments | C7: =ABS('Income Statement'!C35) -> 82 | D7: =ABS('Income Statement'!D35) -> 55 | E7: =ABS('Income Statement'!E35) -> 79.361438 | F7: =ABS('Income Statement'!F35) -> 92.207714 | G7: =ABS('Income Statement'!G35) -> 104.03086 | H7: =ABS('Income Statement'!H35) -> 113.46756 | I7: =ABS('Income Statement'!I35) -> 129.21594
A8: (+) Stock-based compensation & other non-cash items | C8: 220 | D8: 240 | E8: ='Income Statement'!E9*Assumptions!C39 -> 198.4036 | F8: ='Income Statement'!F9*Assumptions!D39 -> 206.11136 | G8: ='Income Statement'!G9*Assumptions!E39 -> 208.06171 | H8: ='Income Statement'!H9*Assumptions!F39 -> 211.80611 | I8: ='Income Statement'!I9*Assumptions!G39 -> 215.3599
A9: (Increase) / decrease in other non-loan assets | C9: =-('Balance Sheet'!C9-'Balance Sheet'!B9) -> -27.55 | D9: =-('Balance Sheet'!D9-'Balance Sheet'!C9) -> -34.9 | E9: =-('Balance Sheet'!E9-'Balance Sheet'!D9) -> -44.99844 | F9: =-('Balance Sheet'!F9-'Balance Sheet'!E9) -> -50.75072 | G9: =-('Balance Sheet'!G9-'Balance Sheet'!F9) -> -53.897265 | H9: =-('Balance Sheet'!H9-'Balance Sheet'!G9) -> -53.128772 | I9: =-('Balance Sheet'!I9-'Balance Sheet'!H9) -> -52.494611
A10: Increase / (decrease) in other liabilities | C10: =('Balance Sheet'!C16-'Balance Sheet'!B16) -> 27.55 | D10: =('Balance Sheet'!D16-'Balance Sheet'!C16) -> 34.9 | E10: =('Balance Sheet'!E16-'Balance Sheet'!D16) -> 44.99844 | F10: =('Balance Sheet'!F16-'Balance Sheet'!E16) -> 50.75072 | G10: =('Balance Sheet'!G16-'Balance Sheet'!F16) -> 53.897265 | H10: =('Balance Sheet'!H16-'Balance Sheet'!G16) -> 53.128772 | I10: =('Balance Sheet'!I16-'Balance Sheet'!H16) -> 52.494611
A11: Net cash from operating activities | C11: =SUM(C6:C10) -> 305 | D11: =SUM(D6:D10) -> 2 | E11: =SUM(E6:E10) -> 367.28022 | F11: =SUM(F6:F10) -> 558.14859 | G11: =SUM(G6:G10) -> 800.69229 | H11: =SUM(H6:H10) -> 1030.4825 | I11: =SUM(I6:I10) -> 1304.9596
A13: This is a standard GAAP-convention indirect-method reconciliation: SBC (and, for FY2024A/25A, the precisely-derived combined SBC/restructuring/payroll-tax non-cash addback — see cell comments) is added back to Net income here because it did not consume cash, even though it is embedded within functional opex lines rather than shown separately on the Income Statement. This differs DELIBERATELY from the DCF Valuation tab, which does NOT add SBC back to unlevered free cash flow — a conservative valuation choice (SBC is real, dilutive economic cost to shareholders) documented on the Income Statement and DCF tabs. The two tabs are intentionally NOT meant to show the same cash-flow figure: this tab is the accounting cash-flow statement; the DCF tab is a deliberately more conservative valuation cash-flow build.
A14: CASH FLOW FROM INVESTING ACTIVITIES
A15: Capital expenditure | C15: =-'Balance Sheet'!C7 -> -62 | D15: =-'Balance Sheet'!D7 -> -74 | E15: =-'Balance Sheet'!E7 -> -88.179376 | F15: =-'Balance Sheet'!F7 -> -103.05568 | G15: =-'Balance Sheet'!G7 -> -117.03471 | H15: =-'Balance Sheet'!H7 -> -128.59657 | I15: =-'Balance Sheet'!I7 -> -137.83034
A16: Increase in net loans to consumers | C16: =-('Balance Sheet'!C6-'Balance Sheet'!B6) -> -1291.614 | D16: =-('Balance Sheet'!D6-'Balance Sheet'!C6) -> -2427.391 | E16: =-('Balance Sheet'!E6-'Balance Sheet'!D6) -> -3146.34 | F16: =-('Balance Sheet'!F6-'Balance Sheet'!E6) -> -3267.0776 | G16: =-('Balance Sheet'!G6-'Balance Sheet'!F6) -> -3210.6174 | H16: =-('Balance Sheet'!H6-'Balance Sheet'!G6) -> -2952.5881 | I16: =-('Balance Sheet'!I6-'Balance Sheet'!H6) -> -2751.6518
A17: Net cash from investing activities | C17: =SUM(C14:C16) -> -1353.614 | D17: =SUM(D14:D16) -> -2501.391 | E17: =SUM(E14:E16) -> -3234.5194 | F17: =SUM(F14:F16) -> -3370.1333 | G17: =SUM(G14:G16) -> -3327.6521 | H17: =SUM(H14:H16) -> -3081.1846 | I17: =SUM(I14:I16) -> -2889.4821
A19: CASH FLOW FROM FINANCING ACTIVITIES
A20: Increase in consumer deposits | C20: =('Balance Sheet'!C14-'Balance Sheet'!B14) -> 1537.3702 | D20: =('Balance Sheet'!D14-'Balance Sheet'!C14) -> 1971.4652 | E20: =('Balance Sheet'!E14-'Balance Sheet'!D14) -> 1661.6768 | F20: =('Balance Sheet'!F14-'Balance Sheet'!E14) -> 2782.4082 | G20: =('Balance Sheet'!G14-'Balance Sheet'!F14) -> 2870.1816 | H20: =('Balance Sheet'!H14-'Balance Sheet'!G14) -> 2797.3434 | I20: =('Balance Sheet'!I14-'Balance Sheet'!H14) -> 2754.6979
A21: Increase in other borrowings | C21: =('Balance Sheet'!C15-'Balance Sheet'!B15) -> -245.75625 | D21: =('Balance Sheet'!D15-'Balance Sheet'!C15) -> 455.92575 | E21: =('Balance Sheet'!E15-'Balance Sheet'!D15) -> 1484.6632 | F21: =('Balance Sheet'!F15-'Balance Sheet'!E15) -> 484.66938 | G21: =('Balance Sheet'!G15-'Balance Sheet'!F15) -> 340.43583 | H21: =('Balance Sheet'!H15-'Balance Sheet'!G15) -> 155.24468 | I21: =('Balance Sheet'!I15-'Balance Sheet'!H15) -> -3.046109
A22: IPO proceeds (net primary issuance) | C22: 0 | D22: =Assumptions!C24 -> 200 | E22: 0 | F22: 0 | G22: 0 | H22: 0 | I22: 0
A23: Net cash from financing activities | C23: =SUM(C19:C22) -> 1291.614 | D23: =SUM(D19:D22) -> 2627.391 | E23: =SUM(E19:E22) -> 3146.34 | F23: =SUM(F19:F22) -> 3267.0776 | G23: =SUM(G19:G22) -> 3210.6174 | H23: =SUM(H19:H22) -> 2952.5881 | I23: =SUM(I19:I22) -> 2751.6518
A25: Net increase / (decrease) in cash | C25: =C11+C17+C23 -> 243 | D25: =D11+D17+D23 -> 128 | E25: =E11+E17+E23 -> 279.10085 | F25: =F11+F17+F23 -> 455.09291 | G25: =G11+G17+G23 -> 683.65758 | H25: =H11+H17+H23 -> 901.88591 | I25: =I11+I17+I23 -> 1167.1292
A26: Beginning cash & cash equivalents | C26: ='Balance Sheet'!B10 -> 2000 | D26: ='Balance Sheet'!C10 -> 2243 | E26: ='Balance Sheet'!D10 -> 2371 | F26: ='Balance Sheet'!E10 -> 2650.1008 | G26: ='Balance Sheet'!F10 -> 3105.1938 | H26: ='Balance Sheet'!G10 -> 3788.8513 | I26: ='Balance Sheet'!H10 -> 4690.7372
A27: Ending cash & cash equivalents | C27: =C26+C25 -> 2243 | D27: =D26+D25 -> 2371 | E27: =E26+E25 -> 2650.1008 | F27: =F26+F25 -> 3105.1938 | G27: =G26+G25 -> 3788.8513 | H27: =H26+H25 -> 4690.7372 | I27: =I26+I25 -> 5857.8664
A30: Indirect-method cash flow statement fully linked to the Income Statement (Net income, D&A, SBC) and Balance Sheet (changes in loans, deposits, other borrowings, other assets/liabilities). Ending cash flows back onto the Balance Sheet's Cash & cash equivalents line, closing the loop of the three-statement model — see the Balance Sheet's "Balance check" row, which should equal zero by construction. FY2025A financing activities include the Company's ~$200mm gross primary IPO proceeds; secondary (selling-shareholder) share sales are excluded as they raise no cash for the Company.

Sheet DCF Valuation
A1: Illustrative Unlevered FCF DCF
A2: $ in millions except per-share data | Unlevered free cash flow, FY2026E–FY2030E explicit period + Gordon Growth terminal value — ONE input to the valuation, not a definitive intrinsic value (see methodology note below)
E4: FY2026E | F4: FY2027E | G4: FY2028E | H4: FY2029E | I4: FY2030E
A5: METHODOLOGY CAVEAT: this tab applies a standard corporate unlevered-FCF DCF (EBIT → NOPAT → +D&A − Capex − ΔNWC → WACC-discounted Enterprise Value). For a regulated financial institution like Klarna — where deposits/wholesale funding ARE the operating capital structure, loan growth consumes regulatory capital, and interest income/expense is integral to the business rather than a financing afterthought — this is a simplified, hybrid treatment, not a conventional bank valuation methodology. A more rigorous banking valuation would typically triangulate P/E, Price/Book (or Price/Tangible Book) and a residual-income / excess-return-on-equity model, using EV/Revenue (see Comps tab) only as a supplemental cross-check. The "Regulatory capital retained to support loan growth" line below is this model's attempt to partially bridge that gap within a standard DCF framework — treat the output here as ONE illustrative data point in the Football Field triangulation, not a definitive intrinsic value.
A7: UNLEVERED FREE CASH FLOW BUILD
A8: Operating profit / (loss) (GAAP, = EBIT) | E8: ='Income Statement'!E36 -> 140.96647 | F8: ='Income Statement'!F36 -> 341.12096 | G8: ='Income Statement'!G36 -> 611.46629 | H8: ='Income Statement'!H36 -> 870.27841 | I8: ='Income Statement'!I36 -> 1163.6628
A9: Less: cash taxes on EBIT | E9: =-MAX(E8,0)*Assumptions!C42 -> -36.651282 | F9: =-MAX(F8,0)*Assumptions!D42 -> -88.691451 | G9: =-MAX(G8,0)*Assumptions!E42 -> -152.86657 | H9: =-MAX(H8,0)*Assumptions!F42 -> -217.5696 | I9: =-MAX(I8,0)*Assumptions!G42 -> -279.27906
A10: Tax-effected operating profit (NOPAT) | E10: =E8+E9 -> 104.31519 | F10: =F8+F9 -> 252.42951 | G10: =G8+G9 -> 458.59972 | H10: =H8+H9 -> 652.70881 | I10: =I8+I9 -> 884.3837
A12: (+) D&A | E12: =ABS('Income Statement'!E35) -> 79.361438 | F12: =ABS('Income Statement'!F35) -> 92.207714 | G12: =ABS('Income Statement'!G35) -> 104.03086 | H12: =ABS('Income Statement'!H35) -> 113.46756 | I12: =ABS('Income Statement'!I35) -> 129.21594
A13: (−) Capital expenditure | E13: =-'Balance Sheet'!E7 -> -88.179376 | F13: =-'Balance Sheet'!F7 -> -103.05568 | G13: =-'Balance Sheet'!G7 -> -117.03471 | H13: =-'Balance Sheet'!H7 -> -128.59657 | I13: =-'Balance Sheet'!I7 -> -137.83034
A14: (−) Increase in other (non-loan) net working capital | E14: =-Assumptions!C44*('Income Statement'!E9-'Income Statement'!D9) -> -26.999064 | F14: =-Assumptions!D44*('Income Statement'!F9-'Income Statement'!E9) -> -30.450432 | G14: =-Assumptions!E44*('Income Statement'!G9-'Income Statement'!F9) -> -32.338359 | H14: =-Assumptions!F44*('Income Statement'!H9-'Income Statement'!G9) -> -31.877263 | I14: =-Assumptions!G44*('Income Statement'!I9-'Income Statement'!H9) -> -31.496767
A15: (−) Regulatory capital retained to support loan growth | E15: =-Assumptions!C48*('Balance Sheet'!E6-'Balance Sheet'!D6) -> -62.9268 | F15: =-Assumptions!D48*('Balance Sheet'!F6-'Balance Sheet'!E6) -> -65.341552 | G15: =-Assumptions!E48*('Balance Sheet'!G6-'Balance Sheet'!F6) -> -80.265436 | H15: =-Assumptions!F48*('Balance Sheet'!H6-'Balance Sheet'!G6) -> -73.814702 | I15: =-Assumptions!G48*('Balance Sheet'!I6-'Balance Sheet'!H6) -> -82.549553
A17: Loan-book growth (net loans to consumers) itself is excluded from unlevered FCF — it is treated as substantially matched-funded by consumer deposits and warehouse/ABS facilities (see Balance Sheet tab), consistent with the short-duration, high-turnover nature of Klarna's receivables and with funding costs already reducing Adjusted Operating Profit above. However, as a licensed bank (Klarna Bank AB) Klarna cannot fund 100% of loan growth with deposits/wholesale debt under Basel III/CRR capital-adequacy rules: a portion of incremental loans must be supported by retained equity capital that is NOT distributable to shareholders. The line above makes this capital-adequacy drag explicit — applying an illustrative 2–3% incremental capital ratio to loan-book growth (a deliberately conservative INCREMENTAL buffer, not a full Basel III/CRR total capital ratio, since ~100% of loan growth is already modeled as debt/deposit-funded on the Balance Sheet — see that tab's capital-ratio comment for the full rationale) — rather than implicitly assuming Klarna can grow its loan book indefinitely at zero capital cost, which would otherwise overstate terminal value for a credit-exposed fintech. See Balance Sheet tab's "Capital Adequacy" memo and the Assumptions tab (Section C) to flex this as a stress-test lever.
A18: Unlevered free cash flow | E18: =SUM(E10,E12,E13,E14,E15) -> 5.5713852 | F18: =SUM(F10,F12,F13,F14,F15) -> 145.78956 | G18: =SUM(G10,G12,G13,G14,G15) -> 332.99207 | H18: =SUM(H10,H12,H13,H14,H15) -> 531.88783 | I18: =SUM(I10,I12,I13,I14,I15) -> 761.72299
A20: DISCOUNTING
A21: Discount period (mid-year convention) | E21: 0.5 | F21: 1.5 | G21: 2.5 | H21: 3.5 | I21: 4.5
A22: Discount factor @ WACC | E22: =1/(1+Assumptions!$C$60)^E21 -> 0.94937184 | F22: =1/(1+Assumptions!$C$60)^F21 -> 0.85567539 | G22: =1/(1+Assumptions!$C$60)^G21 -> 0.77122613 | H22: =1/(1+Assumptions!$C$60)^H21 -> 0.69511143 | I22: =1/(1+Assumptions!$C$60)^I21 -> 0.62650872
A23: PV of unlevered FCF | E23: =E18*E22 -> 5.2893162 | F23: =F18*F22 -> 124.74854 | G23: =G18*G22 -> 256.81218 | H23: =H18*H22 -> 369.72131 | I23: =I18*I22 -> 477.22609
A25: TERMINAL VALUE (GORDON GROWTH)
A26: Final-year (FY2030E) unlevered FCF | E26: =I18 -> 761.72299
A27: Terminal growth rate (g) | E27: =Assumptions!$C$61 -> 0.035
A28: WACC | E28: =Assumptions!$C$60 -> 0.1095
A29: Terminal value (undiscounted, as of FY2030E) | E29: =E26*(1+E27)/(E28-E27) -> 10582.326
A30: Memo: FY2030E EBIT / Operating profit (GAAP) ($mm) | E30: ='Income Statement'!I36 -> 1163.6628
A31: Implied terminal-year EV / EBIT (x) | E31: =E29/E30 -> 9.0939801
A32: Discount factor for terminal value (FY2030E, year-end) | E32: =1/(1+E28)^5 -> 0.59478974
A33: PV of terminal value | E33: =E29*E32 -> 6294.259
A35: ENTERPRISE VALUE → EQUITY VALUE → PER-SHARE VALUE
A36: Sum of PV of explicit-period unlevered FCF | E36: =SUM(E23:I23) -> 1233.7974
A37: (+) PV of terminal value | E37: =E33 -> 6294.259
A38: Implied Enterprise Value | E38: =E36+E37 -> 7528.0564
A39: % of EV from terminal value | E39: =E37/E38 -> 0.83610677
A40: (−) Net debt / (+) net cash at IPO | E40: =Assumptions!$C$25 -> -1200
A41: Implied Equity Value | E41: =E38-E40 -> 8728.0564
A42: Diluted shares outstanding (mm) | E42: =Assumptions!$C$21 -> 377.8
A43: Implied value per share | E43: =E41/E42 -> 23.10232
A45: Memo: Actual IPO price per share | E45: =Assumptions!$C$17 -> 40
A46: Memo: Actual Day-1 close per share | E46: =Assumptions!$C$18 -> 45.82
A47: Implied upside / (downside) vs. IPO price | E47: =E43/E45-1 -> -0.42244201
A49: Mid-year discounting convention applied to the explicit FY2026E–FY2030E period (discount periods 0.5, 1.5, ... 4.5) to reflect cash flows generated evenly throughout each year rather than only at year-end; the terminal value is discounted using a full 5.0-year period as it represents a value as of the end of FY2030E. WACC and terminal growth rate are set on the Assumptions tab (Section D) and can be flexed there or via the Stress Testing tab's two-way sensitivity grid. Terminal-value sanity check: the Gordon Growth terminal value implies an EV/Adjusted-Operating-Profit multiple in the terminal year (see rows above) — a useful cross-check against a plausible steady-state exit multiple for a mature, moderately-levered consumer fintech (for reference, a healthy-but-not-euphoric payments/fintech typically supports high-single-digit to low-double-digit EV/EBIT multiples at maturity).

Sheet Comps - Revenue Multiples
A1: Illustrative Comparable Company Benchmarking — Revenue Multiples
A2: $ in millions except multiples | Illustrative benchmarking of Klarna's IPO pricing against selected payments / consumer-fintech peers — comp market data below is order-of-magnitude/illustrative, not a live market-data feed (see note)
A4: COMPARABLE COMPANY SET
B5: Market Cap | C5: Net Debt/(Cash) | D5: Enterprise Value | E5: LTM Revenue | F5: NTM Revenue | G5: EV / LTM Rev | H5: EV / NTM Rev | I5: LTM Rev Growth
A6: Affirm Holdings (AFRM) | B6: =Assumptions!C78 -> 25000 | C6: =Assumptions!D78 -> 7000 | D6: =B6+C6 -> 32000 | E6: =Assumptions!E78 -> 3200 | F6: =Assumptions!F78 -> 3850 | G6: =D6/E6 -> 10 | H6: =D6/F6 -> 8.3116883 | I6: =Assumptions!G78 -> 0.35
A7: PayPal Holdings (PYPL) | B7: =Assumptions!C79 -> 68000 | C7: =Assumptions!D79 -> -1500 | D7: =B7+C7 -> 66500 | E7: =Assumptions!E79 -> 32300 | F7: =Assumptions!F79 -> 33800 | G7: =D7/E7 -> 2.0588235 | H7: =D7/F7 -> 1.9674556 | I7: =Assumptions!G79 -> 0.05
A8: Block Inc. (XYZ, incl. Afterpay/Cash App) | B8: =Assumptions!C80 -> 46000 | C8: =Assumptions!D80 -> -2600 | D8: =B8+C8 -> 43400 | E8: =Assumptions!E80 -> 24500 | F8: =Assumptions!F80 -> 26400 | G8: =D8/E8 -> 1.7714286 | H8: =D8/F8 -> 1.6439394 | I8: =Assumptions!G80 -> 0.1
A9: Adyen N.V. (ADYEN) | B9: =Assumptions!C81 -> 45000 | C9: =Assumptions!D81 -> -1800 | D9: =B9+C9 -> 43200 | E9: =Assumptions!E81 -> 2100 | F9: =Assumptions!F81 -> 2500 | G9: =D9/E9 -> 20.571429 | H9: =D9/F9 -> 17.28 | I9: =Assumptions!G81 -> 0.22
A10: Mean | G10: =AVERAGE(G6:G9) -> 8.6004202 | H10: =AVERAGE(H6:H9) -> 7.3007708
A11: Median | G11: =MEDIAN(G6:G9) -> 6.0294118 | H11: =MEDIAN(H6:H9) -> 5.139572
A12: Median — Affirm only (direct, pure-play BNPL peer) | G12: =G6 -> 10 | H12: =H6 -> 8.3116883
A14: The broad Mean/Median above are dragged toward the lower end by PayPal and Block, which are large, diversified, lower-growth businesses only partially exposed to BNPL — and by Adyen, which (despite trading at a premium multiple) is a global payments-acquiring platform, not a direct BNPL comparable, so it is excluded from this narrower reference point rather than averaged in as a "BNPL peer." Affirm is the closest direct, pure-play BNPL/consumer-credit comparable to Klarna. This Affirm-only reference point is the more decision-relevant one for BNPL-specific benchmarking and is consistent with the Applied EV/Revenue range (3.0x–5.5x) used below, which sits below Affirm's own multiple — reflecting Klarna's thinner net margins and heavier consumer-credit exposure at IPO relative to Affirm. Consider also SoFi Technologies as a further consumer-fintech reference point in a production comp set (not included here).
A16: APPLIED MULTIPLE RANGE & IMPLIED KLARNA VALUATION
B17: Low | C17: Selected / Mid | D17: High
A18: Applied EV / Revenue multiple (x) | B18: 3 | C18: 4.25 | D18: 5.5
A19: Reference revenue basis | E19: FY2026E Revenue
A20: Klarna FY2026E Revenue ($mm) | B20: ='Income Statement'!E9 -> 4408.9688
A21: Implied Enterprise Value ($mm) | B21: =B18*$B$20 -> 13226.906 | C21: =C18*$B$20 -> 18738.117 | D21: =D18*$B$20 -> 24249.328
A22: (−) Net debt / (+) net cash | B22: =Assumptions!$C$25 -> -1200 | C22: =Assumptions!$C$25 -> -1200 | D22: =Assumptions!$C$25 -> -1200
A23: Implied Equity Value ($mm) | B23: =B21-B22 -> 14426.906 | C23: =C21-C22 -> 19938.117 | D23: =D21-D22 -> 25449.328
A24: Diluted shares outstanding (mm) | B24: =Assumptions!$C$21 -> 377.8 | C24: =Assumptions!$C$21 -> 377.8 | D24: =Assumptions!$C$21 -> 377.8
A25: Implied value per share | B25: =B23/B24 -> 38.186624 | C25: =C23/C24 -> 52.774265 | D25: =D23/D24 -> 67.361907
A27: Applying the Company's actual FY2026E revenue against a 3.0x–5.5x EV/Revenue range (informed by the comp set above and Sacra's reported IPO revenue-multiple target of 3.5–5x) brackets an implied equity value of roughly $12–$23bn, comfortably spanning the $15.1bn IPO price and $19.65bn Day-1 close — see Football Field tab for the full triangulation against the DCF.

Sheet Re-Rating Bridge
A1: Valuation Re-Rating Bridge
A2: $ in millions except per-share and multiple data | Decomposing Klarna's path from $46bn (2021 peak) to $6.7bn (2022 trough) to $15bn (2025 IPO)
A4: VALUATION HISTORY TIMELINE
B5: Mar-2021 | C5: Jun-2021 (Peak) | D5: Jul-2022 (Trough) | E5: Sep-2025 (IPO) | F5: Sep-2025 (Day-1)
A6: Post-money valuation ($mm) | B6: =Assumptions!C72 -> 31000 | C6: =Assumptions!D72 -> 45600 | D6: =Assumptions!E72 -> 6700 | E6: =Assumptions!F72 -> 15100 | F6: =Assumptions!G72 -> 19650
A7: Reference LTM revenue ($mm) | B7: =Assumptions!C73 -> 1850 | C7: =Assumptions!D73 -> 1850 | D7: =Assumptions!E73 -> 2266 | E7: =Assumptions!F73 -> 3509 | F7: =Assumptions!G73 -> 3509
A8: Implied EV / Revenue multiple (x) | B8: =B6/B7 -> 16.756757 | C8: =C6/C7 -> 24.648649 | D8: =D6/D7 -> 2.956752 | E8: =E6/E7 -> 4.3032203 | F8: =F6/F7 -> 5.599886
A9: Change in valuation vs. prior milestone | C9: =C6/B6-1 -> 0.47096774 | D9: =D6/C6-1 -> -0.85307018 | E9: =E6/D6-1 -> 1.2537313 | F9: =F6/E6-1 -> 0.3013245
A11: DECOMPOSITION: REVENUE GROWTH EFFECT vs. MULTIPLE RE-RATING EFFECT
A12: Standard two-factor bridge: ΔValue = (Multiple₀ × ΔRevenue) + (Revenue₁ × ΔMultiple). Decomposes each leg of the valuation history into how much was driven by growing the revenue base vs. how much was driven by the market re-rating the multiple investors were willing to pay for that revenue.
A13: LEG 1: PEAK (JUN-2021) → TROUGH (JUL-2022)
A14: Valuation, Jun-2021 Peak ($mm) | B14: =C6 -> 45600
A15: (+) Revenue growth effect | B15: =C8*(D7-C7) -> 10253.838
A16: (+) Multiple re-rating effect | B16: =D7*(D8-C8) -> -49153.838
A17: Valuation, Jul-2022 Trough ($mm) | B17: =B14+B15+B16 -> 6700
A18: Check vs. actual (should be ~0) | B18: =B17-D6 -> 0
A20: LEG 2: TROUGH (JUL-2022) → IPO (SEP-2025)
A21: Valuation, Jul-2022 Trough ($mm) | B21: =D6 -> 6700
A22: (+) Revenue growth effect | B22: =D8*(E7-D7) -> 3675.2427
A23: (+) Multiple re-rating effect | B23: =E7*(E8-D8) -> 4724.7573
A24: Valuation, Sep-2025 IPO ($mm) | B24: =B21+B22+B23 -> 15100
A25: Check vs. actual (should be ~0) | B25: =B24-E6 -> 0
A27: LEG 3: IPO PRICE → DAY-1 CLOSE (SEP-2025, SAME-DAY)
A28: Valuation, Sep-2025 IPO Price ($mm) | B28: =E6 -> 15100
A29: (+) Revenue growth effect | B29: =E8*(F7-E7) -> 0
A30: (+) Multiple re-rating effect | B30: =F7*(F8-E8) -> 4550
A31: Valuation, Sep-2025 Day-1 Close ($mm) | B31: =B28+B29+B30 -> 19650
A32: Check vs. actual (should be ~0) | B32: =B31-F6 -> 0
A34: WATERFALL SUMMARY (FOR CHART)
A35: Jun-2021 Peak | B35: =C6 -> 45600 | C35: Level
A36: Leg 1: Revenue growth | B36: =B15 -> 10253.838 | C36: Change
A37: Leg 1: Multiple re-rating | B37: =B16 -> -49153.838 | C37: Change
A38: Jul-2022 Trough | B38: =D6 -> 6700 | C38: Level
A39: Leg 2: Revenue growth | B39: =B22 -> 3675.2427 | C39: Change
A40: Leg 2: Multiple re-rating | B40: =B23 -> 4724.7573 | C40: Change
A41: Sep-2025 IPO Price | B41: =E6 -> 15100 | C41: Level
A42: Leg 3: Day-1 pop | B42: =B30+B29 -> 4550 | C42: Change
A43: Sep-2025 Day-1 Close | B43: =F6 -> 19650 | C43: Level
A45: Reading the bridge: the 2021→2022 collapse (-85%) was driven overwhelmingly by multiple compression (growth-at-all-costs euphoria unwinding as rates rose and BNPL regulatory scrutiny increased) rather than a revenue decline — Klarna's revenue continued growing throughout. The 2022→2025 recovery to a $15.1bn IPO price similarly reflects a partial re-rating of the multiple (from a distressed trough level back toward a level that credits Klarna's shift to disciplined, profitable growth) combined with continued revenue growth. The IPO-day pop to $19.65bn reflects order-book oversubscription (~26x, per Investing.com) and first-day price discovery rather than any change in fundamentals.
A46: Chart helper (stacked-bar waterfall construction) | B46: Base (invisible) | C46: Value shown

Sheet Stress Testing
A1: Stress Testing & Sensitivity Analysis
A2: Two-way sensitivity grids flexing WACC/terminal growth and GMV growth/credit-loss assumptions against DCF-implied value per share
A4: GRID 1: WACC vs. TERMINAL GROWTH RATE → IMPLIED VALUE PER SHARE ($)
A5: Recomputes the full DCF (unlevered FCF build unchanged) at each WACC / terminal-growth pair. Base case highlighted.
A6: WACC ↓ / Terminal growth → | B6: 0.025 | C6: 0.03 | D6: 0.035 | E6: 0.04 | F6: 0.045
A7: 0.0895 | B7: =(((('DCF Valuation'!E18/(1+$A7)^0.5)+('DCF Valuation'!F18/(1+$A7)^1.5)+('DCF Valuation'!G18/(1+$A7)^2.5)+('DCF Valuation'!H18/(1+$A7)^3.5)+('DCF Valuation'!I18/(1+$A7)^4.5))+(('DCF Valuation'!I18*(1+B$6)/($A7-B$6))/(1+$A7)^5))-Assumptions!$C$25)/Assumptions!$C$21 -> 27.526949 | C7: =(((('DCF Valuation'!E18/(1+$A7)^0.5)+('DCF Valuation'!F18/(1+$A7)^1.5)+('DCF Valuation'!G18/(1+$A7)^2.5)+('DCF Valuation'!H18/(1+$A7)^3.5)+('DCF Valuation'!I18/(1+$A7)^4.5))+(('DCF Valuation'!I18*(1+C$6)/($A7-C$6))/(1+$A7)^5))-Assumptions!$C$25)/Assumptions!$C$21 -> 29.391265 | D7: =(((('DCF Valuation'!E18/(1+$A7)^0.5)+('DCF Valuation'!F18/(1+$A7)^1.5)+('DCF Valuation'!G18/(1+$A7)^2.5)+('DCF Valuation'!H18/(1+$A7)^3.5)+('DCF Valuation'!I18/(1+$A7)^4.5))+(('DCF Valuation'!I18*(1+D$6)/($A7-D$6))/(1+$A7)^5))-Assumptions!$C$25)/Assumptions!$C$21 -> 31.597657 | E7: =(((('DCF Valuation'!E18/(1+$A7)^0.5)+('DCF Valuation'!F18/(1+$A7)^1.5)+('DCF Valuation'!G18/(1+$A7)^2.5)+('DCF Valuation'!H18/(1+$A7)^3.5)+('DCF Valuation'!I18/(1+$A7)^4.5))+(('DCF Valuation'!I18*(1+E$6)/($A7-E$6))/(1+$A7)^5))-Assumptions!$C$25)/Assumptions!$C$21 -> 34.249785 | F7: =(((('DCF Valuation'!E18/(1+$A7)^0.5)+('DCF Valuation'!F18/(1+$A7)^1.5)+('DCF Valuation'!G18/(1+$A7)^2.5)+('DCF Valuation'!H18/(1+$A7)^3.5)+('DCF Valuation'!I18/(1+$A7)^4.5))+(('DCF Valuation'!I18*(1+F$6)/($A7-F$6))/(1+$A7)^5))-Assumptions!$C$25)/Assumptions!$C$21 -> 37.497897
A8: 0.0995 | B8: =(((('DCF Valuation'!E18/(1+$A8)^0.5)+('DCF Valuation'!F18/(1+$A8)^1.5)+('DCF Valuation'!G18/(1+$A8)^2.5)+('DCF Valuation'!H18/(1+$A8)^3.5)+('DCF Valuation'!I18/(1+$A8)^4.5))+(('DCF Valuation'!I18*(1+B$6)/($A8-B$6))/(1+$A8)^5))-Assumptions!$C$25)/Assumptions!$C$21 -> 23.80961 | C8: =(((('DCF Valuation'!E18/(1+$A8)^0.5)+('DCF Valuation'!F18/(1+$A8)^1.5)+('DCF Valuation'!G18/(1+$A8)^2.5)+('DCF Valuation'!H18/(1+$A8)^3.5)+('DCF Valuation'!I18/(1+$A8)^4.5))+(('DCF Valuation'!I18*(1+C$6)/($A8-C$6))/(1+$A8)^5))-Assumptions!$C$25)/Assumptions!$C$21 -> 25.141852 | D8: =(((('DCF Valuation'!E18/(1+$A8)^0.5)+('DCF Valuation'!F18/(1+$A8)^1.5)+('DCF Valuation'!G18/(1+$A8)^2.5)+('DCF Valuation'!H18/(1+$A8)^3.5)+('DCF Valuation'!I18/(1+$A8)^4.5))+(('DCF Valuation'!I18*(1+D$6)/($A8-D$6))/(1+$A8)^5))-Assumptions!$C$25)/Assumptions!$C$21 -> 26.680643 | E8: =(((('DCF Valuation'!E18/(1+$A8)^0.5)+('DCF Valuation'!F18/(1+$A8)^1.5)+('DCF Valuation'!G18/(1+$A8)^2.5)+('DCF Valuation'!H18/(1+$A8)^3.5)+('DCF Valuation'!I18/(1+$A8)^4.5))+(('DCF Valuation'!I18*(1+E$6)/($A8-E$6))/(1+$A8)^5))-Assumptions!$C$25)/Assumptions!$C$21 -> 28.478054 | F8: =(((('DCF Valuation'!E18/(1+$A8)^0.5)+('DCF Valuation'!F18/(1+$A8)^1.5)+('DCF Valuation'!G18/(1+$A8)^2.5)+('DCF Valuation'!H18/(1+$A8)^3.5)+('DCF Valuation'!I18/(1+$A8)^4.5))+(('DCF Valuation'!I18*(1+F$6)/($A8-F$6))/(1+$A8)^5))-Assumptions!$C$25)/Assumptions!$C$21 -> 30.605266
A9: 0.1095 | B9: =(((('DCF Valuation'!E18/(1+$A9)^0.5)+('DCF Valuation'!F18/(1+$A9)^1.5)+('DCF Valuation'!G18/(1+$A9)^2.5)+('DCF Valuation'!H18/(1+$A9)^3.5)+('DCF Valuation'!I18/(1+$A9)^4.5))+(('DCF Valuation'!I18*(1+B$6)/($A9-B$6))/(1+$A9)^5))-Assumptions!$C$25)/Assumptions!$C$21 -> 20.988768 | C9: =(((('DCF Valuation'!E18/(1+$A9)^0.5)+('DCF Valuation'!F18/(1+$A9)^1.5)+('DCF Valuation'!G18/(1+$A9)^2.5)+('DCF Valuation'!H18/(1+$A9)^3.5)+('DCF Valuation'!I18/(1+$A9)^4.5))+(('DCF Valuation'!I18*(1+C$6)/($A9-C$6))/(1+$A9)^5))-Assumptions!$C$25)/Assumptions!$C$21 -> 21.97908 | D9: =(((('DCF Valuation'!E18/(1+$A9)^0.5)+('DCF Valuation'!F18/(1+$A9)^1.5)+('DCF Valuation'!G18/(1+$A9)^2.5)+('DCF Valuation'!H18/(1+$A9)^3.5)+('DCF Valuation'!I18/(1+$A9)^4.5))+(('DCF Valuation'!I18*(1+D$6)/($A9-D$6))/(1+$A9)^5))-Assumptions!$C$25)/Assumptions!$C$21 -> 23.10232 | E9: =(((('DCF Valuation'!E18/(1+$A9)^0.5)+('DCF Valuation'!F18/(1+$A9)^1.5)+('DCF Valuation'!G18/(1+$A9)^2.5)+('DCF Valuation'!H18/(1+$A9)^3.5)+('DCF Valuation'!I18/(1+$A9)^4.5))+(('DCF Valuation'!I18*(1+E$6)/($A9-E$6))/(1+$A9)^5))-Assumptions!$C$25)/Assumptions!$C$21 -> 24.387177 | F9: =(((('DCF Valuation'!E18/(1+$A9)^0.5)+('DCF Valuation'!F18/(1+$A9)^1.5)+('DCF Valuation'!G18/(1+$A9)^2.5)+('DCF Valuation'!H18/(1+$A9)^3.5)+('DCF Valuation'!I18/(1+$A9)^4.5))+(('DCF Valuation'!I18*(1+F$6)/($A9-F$6))/(1+$A9)^5))-Assumptions!$C$25)/Assumptions!$C$21 -> 25.871236
A10: 0.1195 | B10: =(((('DCF Valuation'!E18/(1+$A10)^0.5)+('DCF Valuation'!F18/(1+$A10)^1.5)+('DCF Valuation'!G18/(1+$A10)^2.5)+('DCF Valuation'!H18/(1+$A10)^3.5)+('DCF Valuation'!I18/(1+$A10)^4.5))+(('DCF Valuation'!I18*(1+B$6)/($A10-B$6))/(1+$A10)^5))-Assumptions!$C$25)/Assumptions!$C$21 -> 18.778972 | C10: =(((('DCF Valuation'!E18/(1+$A10)^0.5)+('DCF Valuation'!F18/(1+$A10)^1.5)+('DCF Valuation'!G18/(1+$A10)^2.5)+('DCF Valuation'!H18/(1+$A10)^3.5)+('DCF Valuation'!I18/(1+$A10)^4.5))+(('DCF Valuation'!I18*(1+C$6)/($A10-C$6))/(1+$A10)^5))-Assumptions!$C$25)/Assumptions!$C$21 -> 19.537818 | D10: =(((('DCF Valuation'!E18/(1+$A10)^0.5)+('DCF Valuation'!F18/(1+$A10)^1.5)+('DCF Valuation'!G18/(1+$A10)^2.5)+('DCF Valuation'!H18/(1+$A10)^3.5)+('DCF Valuation'!I18/(1+$A10)^4.5))+(('DCF Valuation'!I18*(1+D$6)/($A10-D$6))/(1+$A10)^5))-Assumptions!$C$25)/Assumptions!$C$21 -> 20.386469 | E10: =(((('DCF Valuation'!E18/(1+$A10)^0.5)+('DCF Valuation'!F18/(1+$A10)^1.5)+('DCF Valuation'!G18/(1+$A10)^2.5)+('DCF Valuation'!H18/(1+$A10)^3.5)+('DCF Valuation'!I18/(1+$A10)^4.5))+(('DCF Valuation'!I18*(1+E$6)/($A10-E$6))/(1+$A10)^5))-Assumptions!$C$25)/Assumptions!$C$21 -> 21.341868 | F10: =(((('DCF Valuation'!E18/(1+$A10)^0.5)+('DCF Valuation'!F18/(1+$A10)^1.5)+('DCF Valuation'!G18/(1+$A10)^2.5)+('DCF Valuation'!H18/(1+$A10)^3.5)+('DCF Valuation'!I18/(1+$A10)^4.5))+(('DCF Valuation'!I18*(1+F$6)/($A10-F$6))/(1+$A10)^5))-Assumptions!$C$25)/Assumptions!$C$21 -> 22.425509
A11: 0.1295 | B11: =(((('DCF Valuation'!E18/(1+$A11)^0.5)+('DCF Valuation'!F18/(1+$A11)^1.5)+('DCF Valuation'!G18/(1+$A11)^2.5)+('DCF Valuation'!H18/(1+$A11)^3.5)+('DCF Valuation'!I18/(1+$A11)^4.5))+(('DCF Valuation'!I18*(1+B$6)/($A11-B$6))/(1+$A11)^5))-Assumptions!$C$25)/Assumptions!$C$21 -> 17.004085 | C11: =(((('DCF Valuation'!E18/(1+$A11)^0.5)+('DCF Valuation'!F18/(1+$A11)^1.5)+('DCF Valuation'!G18/(1+$A11)^2.5)+('DCF Valuation'!H18/(1+$A11)^3.5)+('DCF Valuation'!I18/(1+$A11)^4.5))+(('DCF Valuation'!I18*(1+C$6)/($A11-C$6))/(1+$A11)^5))-Assumptions!$C$25)/Assumptions!$C$21 -> 17.599776 | D11: =(((('DCF Valuation'!E18/(1+$A11)^0.5)+('DCF Valuation'!F18/(1+$A11)^1.5)+('DCF Valuation'!G18/(1+$A11)^2.5)+('DCF Valuation'!H18/(1+$A11)^3.5)+('DCF Valuation'!I18/(1+$A11)^4.5))+(('DCF Valuation'!I18*(1+D$6)/($A11-D$6))/(1+$A11)^5))-Assumptions!$C$25)/Assumptions!$C$21 -> 18.258502 | E11: =(((('DCF Valuation'!E18/(1+$A11)^0.5)+('DCF Valuation'!F18/(1+$A11)^1.5)+('DCF Valuation'!G18/(1+$A11)^2.5)+('DCF Valuation'!H18/(1+$A11)^3.5)+('DCF Valuation'!I18/(1+$A11)^4.5))+(('DCF Valuation'!I18*(1+E$6)/($A11-E$6))/(1+$A11)^5))-Assumptions!$C$25)/Assumptions!$C$21 -> 18.99083 | F11: =(((('DCF Valuation'!E18/(1+$A11)^0.5)+('DCF Valuation'!F18/(1+$A11)^1.5)+('DCF Valuation'!G18/(1+$A11)^2.5)+('DCF Valuation'!H18/(1+$A11)^3.5)+('DCF Valuation'!I18/(1+$A11)^4.5))+(('DCF Valuation'!I18*(1+F$6)/($A11-F$6))/(1+$A11)^5))-Assumptions!$C$25)/Assumptions!$C$21 -> 19.809823
A13: Memo: base-case WACC (Assumptions tab) | B13: =Assumptions!$C$60 -> 0.1095
A14: Memo: base-case terminal growth (Assumptions tab) | B14: =Assumptions!$C$61 -> 0.035
A16: GRID 2: FY2026E GMV GROWTH vs. CREDIT-LOSS RATE (% OF GMV) → IMPLIED VALUE PER SHARE ($)
A17: Flexes the single most important growth lever (FY2026E GMV growth, with all subsequent years' growth shifted by the same delta) and the single most important credit/profitability lever (FY2026E credit-loss rate as %GMV, with subsequent years shifted by the same delta) simultaneously through the full 3-statement model and DCF. This directly pressure-tests the profitability inflection Klarna reached in FY2024–FY2025 (its first annual profit, then a return to net loss amid IPO-related SBC/one-offs) against a deterioration in underwriting quality or a growth slowdown.
A18: GMV growth Δ ↓ / Credit-loss rate Δ → | B18: 0.003 | C18: 0.0015 | D18: 0 | E18: -0.0015 | F18: -0.003
